Workbook

Sheet 前台好评提成录入
B1: 前台好评提成明细
B2: 酒店名称：
A3: 序号 | B3: 人员姓名 | C3: 平台 | D3: 单位 | E3: 单价（根据实际情况填写） | G3: 金额 | H3: 1号 | I3: 2号 | J3: 3号 | K3: 4号 | L3: 5号 | M3: 6号 | N3: 7号 | O3: 8号 | P3: 9号 | Q3: 10号 | R3: 11号 | S3: 12号 | T3: 13号 | U3: 14号 | V3: 15号 | W3: 16号 | X3: 17号 | Y3: 18号 | Z3: 19号 | AA3: 20号 | AB3: 21号 | AC3: 22号 | AD3: 23号 | AE3: 24号 | AF3: 25号 | AG3: 26号 | AH3: 27号 | AI3: 28号 | AJ3: 29号 | AK3: 30号 | AL3: 31号
F4: 好评数 | H4: 好评数 | I4: 好评数 | J4: 好评数 | K4: 好评数 | L4: 好评数 | M4: 好评数 | N4: 好评数 | O4: 好评数 | P4: 好评数 | Q4: 好评数 | R4: 好评数 | S4: 好评数 | T4: 好评数 | U4: 好评数 | V4: 好评数 | W4: 好评数 | X4: 好评数 | Y4: 好评数 | Z4: 好评数 | AA4: 好评数 | AB4: 好评数 | AC4: 好评数 | AD4: 好评数 | AE4: 好评数 | AF4: 好评数 | AG4: 好评数 | AH4: 好评数 | AI4: 好评数 | AJ4: 好评数 | AK4: 好评数 | AL4: 好评数
A5: 1 | B5: 张馨月 | C5: 携程 | D5: 条 | E5: 6 | F5: =SUMIF($H$4:$AL$4,$F$4,$H5:$AL5) -> 65 | G5: =+E5*F5 -> 390 | H5: 65
A6: 2 | B6: 张馨月 | C6: 携程优质 | D6: 条 | E6: 15 | F6: =SUMIF($H$4:$AL$4,$F$4,$H6:$AL6) -> 32 | G6: =F6*E6 -> 480 | H6: 32
A7: 3 | B7: 张馨月 | C7: 黑/金优质 | D7: 条 | E7: 30 | F7: =SUMIF($H$4:$AL$4,$F$4,$H7:$AL7) -> 0 | G7: =F7*E7 -> 0
A8: 4 | B8: 张馨月 | C8: 去哪儿 | D8: 条 | E8: 6 | F8: =SUMIF($H$4:$AL$4,$F$4,$H8:$AL8) -> 0 | G8: =+E8*F8 -> 0
A9: 5 | B9: 张馨月 | C9: 同程 | D9: 条 | E9: 6 | F9: =SUMIF($H$4:$AL$4,$F$4,$H9:$AL9) -> 0 | G9: =+E9*F9 -> 0
A10: 6 | B10: 张馨月 | C10: 智行 | D10: 条 | E10: 6 | F10: =SUMIF($H$4:$AL$4,$F$4,$H10:$AL10) -> 0 | G10: =+E10*F10 -> 0
A11: 7 | B11: 张馨月 | C11: 抖音 | D11: 条 | E11: 6 | F11: =SUMIF($H$4:$AL$4,$F$4,$H11:$AL11) -> 0 | G11: =+E11*F11 -> 0
A12: 8 | B12: 张馨月 | C12: 美团 | D12: 条 | E12: 6 | F12: =SUMIF($H$4:$AL$4,$F$4,$H12:$AL12) -> 1 | G12: =+E12*F12 -> 6 | H12: 1
A13: 9 | B13: 张馨月 | C13: 飞猪 | D13: 条 | E13: 6 | F13: =SUMIF($H$4:$AL$4,$F$4,$H13:$AL13) -> 0 | G13: =+E13*F13 -> 0
A14: 10 | B14: 张馨月 | C14: 官网 | D14: 条 | E14: 6 | F14: =SUMIF($H$4:$AL$4,$F$4,$H14:$AL14) -> 1 | G14: =F14*E14 -> 6 | H14: 1
A15: 11 | B15: 徐嘉瑜 | C15: 携程 | D15: 条 | E15: 5 | F15: =SUMIF($H$4:$AL$4,$F$4,$H15:$AL15) -> 4 | G15: =+E15*F15 -> 20 | H15: 4
A16: 12 | B16: 徐嘉瑜 | C16: 携程优质 | D16: 条 | E16: 15 | F16: =SUMIF($H$4:$AL$4,$F$4,$H16:$AL16) -> 1 | G16: =F16*E16 -> 15 | H16: 1
A17: 13 | B17: 徐嘉瑜 | C17: 黑/金优质 | D17: 条 | E17: 30 | F17: =SUMIF($H$4:$AL$4,$F$4,$H17:$AL17) -> 0 | G17: =F17*E17 -> 0
A18: 14 | B18: 徐嘉瑜 | C18: 去哪儿 | D18: 条 | E18: 5 | F18: =SUMIF($H$4:$AL$4,$F$4,$H18:$AL18) -> 0 | G18: =+E18*F18 -> 0
A19: 15 | B19: 徐嘉瑜 | C19: 同程 | D19: 条 | E19: 5 | F19: =SUMIF($H$4:$AL$4,$F$4,$H19:$AL19) -> 1 | G19: =+E19*F19 -> 5 | H19: 1
A20: 16 | B20: 徐嘉瑜 | C20: 智行 | D20: 条 | E20: 5 | F20: =SUMIF($H$4:$AL$4,$F$4,$H20:$AL20) -> 0 | G20: =+E20*F20 -> 0
A21: 17 | B21: 徐嘉瑜 | C21: 抖音 | D21: 条 | E21: 5 | F21: =SUMIF($H$4:$AL$4,$F$4,$H21:$AL21) -> 2 | G21: =+E21*F21 -> 10 | H21: 2
A22: 18 | B22: 徐嘉瑜 | C22: 美团 | D22: 条 | E22: 5 | F22: =SUMIF($H$4:$AL$4,$F$4,$H22:$AL22) -> 20 | G22: =+E22*F22 -> 100 | H22: 20
A23: 19 | B23: 徐嘉瑜 | C23: 飞猪 | D23: 条 | E23: 5 | F23: =SUMIF($H$4:$AL$4,$F$4,$H23:$AL23) -> 1 | G23: =+E23*F23 -> 5 | H23: 1
A24: 20 | B24: 徐嘉瑜 | C24: 官网 | D24: 条 | E24: 5 | F24: =SUMIF($H$4:$AL$4,$F$4,$H24:$AL24) -> 7 | G24: =+E24*F24 -> 35 | H24: 7
A25: 21 | B25: 王增 | C25: 携程 | D25: 条 | E25: 5 | F25: =SUMIF($H$4:$AL$4,$F$4,$H25:$AL25) -> 0 | G25: =+E25*F25 -> 0
A26: 22 | B26: 王增 | C26: 携程优质 | D26: 条 | E26: 15 | F26: =SUMIF($H$4:$AL$4,$F$4,$H26:$AL26) -> 2 | G26: =F26*E26 -> 30 | H26: 2
A27: 23 | B27: 王增 | C27: 黑/金优质 | D27: 条 | E27: 30 | F27: =SUMIF($H$4:$AL$4,$F$4,$H27:$AL27) -> 1 | G27: =F27*E27 -> 30 | H27: 1
A28: 24 | B28: 王增 | C28: 去哪儿 | D28: 条 | E28: 5 | F28: =SUMIF($H$4:$AL$4,$F$4,$H28:$AL28) -> 4 | G28: =+E28*F28 -> 20 | H28: 4
A29: 25 | B29: 王增 | C29: 同程 | D29: 条 | E29: 5 | F29: =SUMIF($H$4:$AL$4,$F$4,$H29:$AL29) -> 1 | G29: =+E29*F29 -> 5 | H29: 1
A30: 26 | B30: 王增 | C30: 智行 | D30: 条 | E30: 5 | F30: =SUMIF($H$4:$AL$4,$F$4,$H30:$AL30) -> 0 | G30: =+E30*F30 -> 0
A31: 27 | B31: 王增 | C31: 抖音 | D31: 条 | E31: 5 | F31: =SUMIF($H$4:$AL$4,$F$4,$H31:$AL31) -> 14 | G31: =+E31*F31 -> 70 | H31: 14
A32: 28 | B32: 王增 | C32: 美团 | D32: 条 | E32: 5 | F32: =SUMIF($H$4:$AL$4,$F$4,$H32:$AL32) -> 50 | G32: =+E32*F32 -> 250 | H32: 50
A33: 29 | B33: 王增 | C33: 飞猪 | D33: 条 | E33: 5 | F33: =SUMIF($H$4:$AL$4,$F$4,$H33:$AL33) -> 1 | G33: =+E33*F33 -> 5 | H33: 1
A34: 30 | B34: 王增 | C34: 官网 | D34: 条 | E34: 5 | F34: =SUMIF($H$4:$AL$4,$F$4,$H34:$AL34) -> 26 | G34: =+E34*F34 -> 130 | H34: 26
A35: 31 | B35: 翟芮瑶 | C35: 携程 | D35: 条 | E35: 5 | F35: =SUMIF($H$4:$AL$4,$F$4,$H35:$AL35) -> 2 | G35: =F35*E35 -> 10 | H35: 2
A36: 32 | B36: 翟芮瑶 | C36: 携程优质 | D36: 条 | E36: 15 | F36: =SUMIF($H$4:$AL$4,$F$4,$H36:$AL36) -> 7 | G36: =F36*E36 -> 105 | H36: 7
A37: 33 | B37: 翟芮瑶 | C37: 黑/金优质 | D37: 条 | E37: 30 | F37: =SUMIF($H$4:$AL$4,$F$4,$H37:$AL37) -> 2 | G37: =F37*E37 -> 60 | H37: 2
A38: 34 | B38: 翟芮瑶 | C38: 去哪儿 | D38: 条 | E38: 5 | F38: =SUMIF($H$4:$AL$4,$F$4,$H38:$AL38) -> 3 | G38: =F38*E38 -> 15 | H38: 3
A39: 35 | B39: 翟芮瑶 | C39: 同程 | D39: 条 | E39: 5 | F39: =SUMIF($H$4:$AL$4,$F$4,$H39:$AL39) -> 0 | G39: =F39*E39 -> 0
A40: 36 | B40: 翟芮瑶 | C40: 智行 | D40: 条 | E40: 5 | F40: =SUMIF($H$4:$AL$4,$F$4,$H40:$AL40) -> 0 | G40: =F40*E40 -> 0
...

Sheet 前台二维码提成录入
B1: 前台二维码提成明细
B2: 酒店名称：
A3: 序号 | B3: 人员姓名 | C3: 平台 | D3: 单位 | E3: 单价 | G3: 出库金额 | H3: 1号 | I3: 2号 | J3: 3号 | K3: 4号 | L3: 5号 | M3: 6号 | N3: 7号 | O3: 8号 | P3: 9号 | Q3: 10号 | R3: 11号 | S3: 12号 | T3: 13号 | U3: 14号 | V3: 15号 | W3: 16号 | X3: 17号 | Y3: 18号 | Z3: 19号 | AA3: 20号 | AB3: 21号 | AC3: 22号 | AD3: 23号 | AE3: 24号 | AF3: 25号 | AG3: 26号 | AH3: 27号 | AI3: 28号 | AJ3: 29号 | AK3: 30号 | AL3: 31号
F4: 服务次数 | H4: 服务次数 | I4: 服务次数 | J4: 服务次数 | K4: 服务次数 | L4: 服务次数 | M4: 服务次数 | N4: 服务次数 | O4: 服务次数 | P4: 服务次数 | Q4: 服务次数 | R4: 服务次数 | S4: 服务次数 | T4: 服务次数 | U4: 服务次数 | V4: 服务次数 | W4: 服务次数 | X4: 服务次数 | Y4: 服务次数 | Z4: 服务次数 | AA4: 服务次数 | AB4: 服务次数 | AC4: 服务次数 | AD4: 服务次数 | AE4: 服务次数 | AF4: 服务次数 | AG4: 服务次数 | AH4: 服务次数 | AI4: 服务次数 | AJ4: 服务次数 | AK4: 服务次数 | AL4: 服务次数
A5: 1 | B5: 李龙梅 | C5: 洗衣 | D5: 次 | E5: 1.5 | F5: =SUMIF($H$4:$AL$4,$F$4,$H5:$AL5) -> 3 | G5: =+E5*F5 -> 4.5 | O5: 1 | AE5: 1 | AF5: 1
A6: 2 | B6: 李龙梅 | C6: 送物品 | D6: 次 | E6: 0.5 | F6: =SUMIF($H$4:$AL$4,$F$4,$H6:$AL6) -> 63 | G6: =+E6*F6 -> 31.5 | J6: 11 | K6: 2 | L6: 3 | M6: 3 | O6: 5 | P6: 20 | S6: 2 | AE6: 6 | AG6: 8 | AL6: 3
A7: 3 | B7: 李龙梅 | C7: 点名表扬 | D7: 次 | E7: 1 | F7: =SUMIF($H$4:$AL$4,$F$4,$H7:$AL7) -> 0 | G7: =+E7*F7 -> 0
A8: 4 | B8: 李龙梅 | C8: 违规 | D8: 次 | E8: -2 | F8: =SUMIF($H$4:$AL$4,$F$4,$H8:$AL8) -> 0 | G8: =+E8*F8 -> 0
A9: 5 | B9: 李龙梅 | C9: 其他 | D9: 次 | E9: 2 | F9: =SUMIF($H$4:$AL$4,$F$4,$H9:$AL9) -> 0 | G9: =+E9*F9 -> 0
A10: 6 | B10: 于子杭 | C10: 洗衣 | D10: 次 | E10: 1.5 | F10: =SUMIF($H$4:$AL$4,$F$4,$H10:$AL10) -> 0 | G10: =+E10*F10 -> 0
A11: 7 | B11: 于子杭 | C11: 送物品 | D11: 次 | E11: 0.5 | F11: =SUMIF($H$4:$AL$4,$F$4,$H11:$AL11) -> 67 | G11: =+E11*F11 -> 33.5 | J11: 11 | L11: 3 | M11: 3 | O11: 5 | P11: 20 | R11: 2 | S11: 3 | Z11: 2 | AE11: 6 | AG11: 8 | AK11: 2 | AL11: 2
A12: 8 | B12: 于子杭 | C12: 点名表扬 | D12: 次 | E12: 1 | F12: =SUMIF($H$4:$AL$4,$F$4,$H12:$AL12) -> 0 | G12: =+E12*F12 -> 0
A13: 9 | B13: 于子杭 | C13: 违规 | D13: 次 | E13: -2 | F13: =SUMIF($H$4:$AL$4,$F$4,$H13:$AL13) -> 0 | G13: =+E13*F13 -> 0
A14: 10 | B14: 于子杭 | C14: 其他 | D14: 次 | E14: 2 | F14: =SUMIF($H$4:$AL$4,$F$4,$H14:$AL14) -> 0 | G14: =+E14*F14 -> 0
A15: 11 | B15: 张馨月 | C15: 洗衣 | D15: 次 | E15: 1.5 | F15: =SUMIF($H$4:$AL$4,$F$4,$H15:$AL15) -> 1 | G15: =+E15*F15 -> 1.5 | P15: 1
A16: 12 | B16: 张馨月 | C16: 送物品 | D16: 次 | E16: 0.5 | F16: =SUMIF($H$4:$AL$4,$F$4,$H16:$AL16) -> 70 | G16: =+E16*F16 -> 35 | J16: 11 | K16: 2 | L16: 3 | M16: 3 | O16: 5 | P16: 20 | R16: 2 | S16: 3 | AA16: 3 | AE16: 6 | AG16: 8 | AK16: 2 | AL16: 2
A17: 13 | B17: 张馨月 | C17: 点名表扬 | D17: 次 | E17: 1 | F17: =SUMIF($H$4:$AL$4,$F$4,$H17:$AL17) -> 0 | G17: =+E17*F17 -> 0
A18: 14 | B18: 张馨月 | C18: 违规 | D18: 次 | E18: -2 | F18: =SUMIF($H$4:$AL$4,$F$4,$H18:$AL18) -> 0 | G18: =+E18*F18 -> 0
A19: 15 | B19: 张馨月 | C19: 其他 | D19: 次 | E19: 2 | F19: =SUMIF($H$4:$AL$4,$F$4,$H19:$AL19) -> 0 | G19: =+E19*F19 -> 0
A20: 16 | B20: 王增 | C20: 洗衣 | D20: 次 | E20: 1.5 | F20: =SUMIF($H$4:$AL$4,$F$4,$H20:$AL20) -> 15 | G20: =+E20*F20 -> 22.5 | R20: 4 | S20: 3 | U20: 1 | V20: 2 | X20: 2 | Y20: 1 | AJ20: 1 | AK20: 1
A21: 17 | B21: 王增 | C21: 送物品 | D21: 次 | E21: 0.5 | F21: =SUMIF($H$4:$AL$4,$F$4,$H21:$AL21) -> 121 | G21: =+E21*F21 -> 60.5 | I21: 1 | L21: 12 | M21: 12 | N21: 3 | Q21: 20 | R21: 15 | S21: 10 | X21: 10 | Y21: 11 | AD21: 9 | AE21: 5 | AJ21: 3 | AK21: 10
A22: 18 | B22: 王增 | C22: 点名表扬 | D22: 次 | E22: 1 | F22: =SUMIF($H$4:$AL$4,$F$4,$H22:$AL22) -> 0 | G22: =+E22*F22 -> 0
A23: 19 | B23: 王增 | C23: 违规 | D23: 次 | E23: -2 | F23: =SUMIF($H$4:$AL$4,$F$4,$H23:$AL23) -> 0 | G23: =+E23*F23 -> 0
A24: 20 | B24: 王增 | C24: 其他 | D24: 次 | E24: 2 | F24: =SUMIF($H$4:$AL$4,$F$4,$H24:$AL24) -> 0 | G24: =+E24*F24 -> 0
A25: 21 | B25: 宋雨霏 | C25: 洗衣 | D25: 次 | E25: 1.5 | F25: =SUMIF($H$4:$AL$4,$F$4,$H25:$AL25) -> 6 | G25: =+E25*F25 -> 9 | M25: 1 | S25: 1 | Y25: 2 | AJ25: 1 | AK25: 1
A26: 22 | B26: 宋雨霏 | C26: 送物品 | D26: 次 | E26: 0.5 | F26: =SUMIF($H$4:$AL$4,$F$4,$H26:$AL26) -> 114 | G26: =+E26*F26 -> 57 | L26: 12 | M26: 12 | O26: 2 | Q26: 15 | R26: 15 | S26: 10 | X26: 10 | Y26: 10 | AD26: 9 | AE26: 5 | AJ26: 4 | AK26: 10
A27: 23 | B27: 宋雨霏 | C27: 点名表扬 | D27: 次 | E27: 1 | F27: =SUMIF($H$4:$AL$4,$F$4,$H27:$AL27) -> 0 | G27: =+E27*F27 -> 0
A28: 24 | B28: 宋雨霏 | C28: 违规 | D28: 次 | E28: -2 | F28: =SUMIF($H$4:$AL$4,$F$4,$H28:$AL28) -> 0 | G28: =+E28*F28 -> 0
A29: 25 | B29: 宋雨霏 | C29: 其他 | D29: 次 | E29: 2 | F29: =SUMIF($H$4:$AL$4,$F$4,$H29:$AL29) -> 0 | G29: =+E29*F29 -> 0
A30: 26 | B30: 翟芮瑶 | C30: 洗衣 | D30: 次 | E30: 1.5 | F30: =SUMIF($H$4:$AL$4,$F$4,$H30:$AL30) -> 6 | G30: =+E30*F30 -> 9 | P30: 2 | T30: 1 | V30: 2 | W30: 1
A31: 27 | B31: 翟芮瑶 | C31: 送物品 | D31: 次 | E31: 0.5 | F31: =SUMIF($H$4:$AL$4,$F$4,$H31:$AL31) -> 77 | G31: =+E31*F31 -> 38.5 | J31: 3 | K31: 5 | L31: 1 | P31: 20 | V31: 12 | W31: 4 | AB31: 12 | AH31: 10 | AI31: 10
A32: 28 | B32: 翟芮瑶 | C32: 点名表扬 | D32: 次 | E32: 1 | F32: =SUMIF($H$4:$AL$4,$F$4,$H32:$AL32) -> 0 | G32: =+E32*F32 -> 0
A33: 29 | B33: 翟芮瑶 | C33: 违规 | D33: 次 | E33: -2 | F33: =SUMIF($H$4:$AL$4,$F$4,$H33:$AL33) -> 0 | G33: =+E33*F33 -> 0
A34: 30 | B34: 翟芮瑶 | C34: 其他 | D34: 次 | E34: 2 | F34: =SUMIF($H$4:$AL$4,$F$4,$H34:$AL34) -> 0 | G34: =+E34*F34 -> 0
A35: 31 | B35: 孙源 | C35: 洗衣 | D35: 次 | E35: 1.5 | F35: =SUMIF($H$4:$AL$4,$F$4,$H35:$AL35) -> 8 | G35: =+E35*F35 -> 12 | P35: 1 | V35: 2 | W35: 1 | Y35: 1 | AB35: 1 | AC35: 1 | AI35: 1
A36: 32 | B36: 孙源 | C36: 送物品 | D36: 次 | E36: 0.5 | F36: =SUMIF($H$4:$AL$4,$F$4,$H36:$AL36) -> 77 | G36: =+E36*F36 -> 38.5 | J36: 11 | P36: 20 | V36: 12 | W36: 4 | AB36: 10 | AH36: 10 | AI36: 10
A37: 33 | B37: 孙源 | C37: 点名表扬 | D37: 次 | E37: 1 | F37: =SUMIF($H$4:$AL$4,$F$4,$H37:$AL37) -> 0 | G37: =+E37*F37 -> 0
A38: 34 | B38: 孙源 | C38: 违规 | D38: 次 | E38: -2 | F38: =SUMIF($H$4:$AL$4,$F$4,$H38:$AL38) -> 0 | G38: =+E38*F38 -> 0
A39: 35 | B39: 孙源 | C39: 其他 | D39: 次 | E39: 2 | F39: =SUMIF($H$4:$AL$4,$F$4,$H39:$AL39) -> 0 | G39: =+E39*F39 -> 0
A40: 36 | B40: 吴怡 | C40: 洗衣 | D40: 次 | E40: 1.5 | F40: =SUMIF($H$4:$AL$4,$F$4,$H40:$AL40) -> 5 | G40: =+E40*F40 -> 7.5 | I40: 1 | T40: 1 | U40: 1 | X40: 2
...

Sheet 前台工资录入
A1: 姓名 | B1: 部门 | C1: 岗位 | D1: 是否转正 | E1: 薪等 | F1: 薪级 | G1: 总工资 | H1: 基本工资 | I1: 岗位工资 | J1: 绩效工资 | K1: 出勤天数 | L1: 1号工作时长 | M1: 2号工作时长 | N1: 3号工作时长 | O1: 4号工作时长 | P1: 5号工作时长 | Q1: 6号工作时长 | R1: 7号工作时长 | S1: 8号工作时长 | T1: 9号工作时长 | U1: 10号工作时长 | V1: 11号工作时长 | W1: 12号工作时长 | X1: 13号工作时长 | Y1: 14号工作时长 | Z1: 15号工作时长 | AA1: 16号工作时长 | AB1: 17号工作时长 | AC1: 18号工作时长 | AD1: 19号工作时长 | AE1: 20号工作时长 | AF1: 21号工作时长 | AG1: 22号工作时长 | AH1: 23号工作时长 | AI1: 24号工作时长 | AJ1: 25号工作时长 | AK1: 26号工作时长 | AL1: 27号工作时长 | AM1: 28号工作时长 | AN1: 29号工作时长 | AO1: 30号工作时长 | AP1: 31号工作时长
A2: 李龙梅 | B2: 前厅 | C2: 前台 | D2: 是 | G2: =H2+I2+J2 -> 4500 | H2: 4050 | I2: 0 | J2: 450 | K2: 25 | L2: 0 | M2: 8 | N2: 8 | O2: 8 | P2: 8 | Q2: 8 | R2: 8 | S2: 8 | T2: 8 | U2: 8 | V2: 0 | W2: 8 | X2: 8 | Y2: 8 | Z2: 8 | AA2: 0 | AB2: 8 | AC2: 8 | AD2: 8 | AE2: 8 | AF2: 4 | AG2: 8 | AH2: 8 | AI2: 8 | AJ2: 8 | AK2: 8 | AL2: 8 | AM2: 8 | AN2: 8 | AO2: 8 | AP2: 4
A3: 于子杭 | B3: 前厅 | C3: 前厅领班 | D3: 是 | G3: =H3+I3+J3 -> 4500 | H3: 4050 | I3: 0 | J3: 450 | K3: 25 | L3: 8 | M3: 8 | N3: 8 | O3: 0 | P3: 8 | Q3: 8 | R3: 8 | S3: 8 | T3: 8 | U3: 0 | V3: 8 | W3: 8 | X3: 8 | Y3: 0 | Z3: 8 | AA3: 8 | AB3: 8 | AC3: 8 | AD3: 8 | AE3: 8 | AF3: 8 | AG3: 0 | AH3: 8 | AI3: 8 | AJ3: 8 | AK3: 8 | AL3: 8 | AM3: 8 | AN3: 8 | AO3: 8 | AP3: 8
A4: 张馨月 | B4: 前厅 | C4: 服务经理 | D4: 是 | G4: 4000 | H4: 4000 | I4: 0 | J4: 0 | K4: 25 | L4: 8 | M4: 0 | N4: 8 | O4: 8 | P4: 8 | Q4: 8 | R4: 8 | S4: 8 | T4: 0 | U4: 8 | V4: 8 | W4: 8 | X4: 8 | Y4: 8 | Z4: 8 | AA4: 8 | AB4: 8 | AC4: 8 | AD4: 0 | AE4: 8 | AF4: 8 | AG4: 8 | AH4: 8 | AI4: 0 | AJ4: 8 | AK4: 8 | AL4: 8 | AM4: 8 | AN4: 8 | AO4: 8 | AP4: 8
A5: 徐嘉瑜 | B5: 前厅 | C5: 前台 | D5: 是 | G5: 3500 | H5: 3500 | I5: 0 | J5: 0 | K5: 20 | L5: 12 | M5: 12 | N5: 12 | O5: 12 | P5: 0 | Q5: 0 | R5: 12 | S5: 12 | T5: 12 | U5: 12 | V5: 0 | W5: 0 | X5: 12 | Y5: 12 | Z5: 0 | AA5: 4 | AB5: 0 | AC5: 0 | AD5: 12 | AE5: 12 | AF5: 12 | AG5: 12 | AH5: 0 | AI5: 0 | AJ5: 12 | AK5: 12 | AL5: 12 | AM5: 12 | AN5: 0 | AO5: 0 | AP5: 12
A6: 王增 | B6: 前厅 | C6: 前台 | D6: 是 | G6: 3500 | H6: 3500 | I6: 0 | J6: 0 | K6: 20 | L6: 12 | M6: 12 | N6: 0 | O6: 0 | P6: 12 | Q6: 12 | R6: 12 | S6: 12 | T6: 0 | U6: 0 | V6: 12 | W6: 12 | X6: 12 | Y6: 12 | Z6: 0 | AA6: 0 | AB6: 12 | AC6: 12 | AD6: 12 | AE6: 12 | AF6: 0 | AG6: 0 | AH6: 12 | AI6: 12 | AJ6: 12 | AK6: 12 | AL6: 0 | AM6: 0 | AN6: 12 | AO6: 12 | AP6: 12
A7: 宋雨霏 | B7: 前厅 | C7: 前台 | D7: 是 | G7: 3500 | H7: 3500 | I7: 0 | J7: 0 | K7: 20 | L7: 12 | M7: 12 | N7: 0 | O7: 0 | P7: 12 | Q7: 12 | R7: 12 | S7: 12 | T7: 0 | U7: 0 | V7: 12 | W7: 12 | X7: 12 | Y7: 12 | Z7: 0 | AA7: 0 | AB7: 12 | AC7: 12 | AD7: 12 | AE7: 12 | AF7: 0 | AG7: 0 | AH7: 12 | AI7: 12 | AJ7: 12 | AK7: 12 | AL7: 0 | AM7: 0 | AN7: 12 | AO7: 12 | AP7: 12
A8: 翟芮瑶 | B8: 前厅 | C8: 前台 | D8: 是 | G8: 3500 | H8: 3500 | I8: 0 | J8: 0 | K8: 20 | L8: 0 | M8: 0 | N8: 0 | O8: 12 | P8: 12 | Q8: 12 | R8: 0 | S8: 0 | T8: 12 | U8: 12 | V8: 12 | W8: 12 | X8: 0 | Y8: 0 | Z8: 12 | AA8: 12 | AB8: 12 | AC8: 12 | AD8: 0 | AE8: 0 | AF8: 12 | AG8: 12 | AH8: 12 | AI8: 12 | AJ8: 0 | AK8: 0 | AL8: 12 | AM8: 12 | AN8: 12 | AO8: 12 | AP8: 0
A9: 孙源 | B9: 前厅 | C9: 前台 | D9: 是 | G9: 3500 | H9: 3500 | I9: 0 | J9: 0 | K9: 20 | L9: 0 | M9: 0 | N9: 12 | O9: 0 | P9: 12 | Q9: 12 | R9: 0 | S9: 0 | T9: 12 | U9: 12 | V9: 12 | W9: 12 | X9: 0 | Y9: 0 | Z9: 12 | AA9: 12 | AB9: 12 | AC9: 12 | AD9: 0 | AE9: 0 | AF9: 12 | AG9: 12 | AH9: 12 | AI9: 12 | AJ9: 0 | AK9: 0 | AL9: 0 | AM9: 12 | AN9: 12 | AO9: 12 | AP9: 0
A10: 吴怡 | B10: 前厅 | C10: 前台 | G10: 3500 | H10: 3500 | I10: 0 | J10: 0 | K10: 20 | L10: 12 | M10: 12 | N10: 12 | O10: 12 | P10: 0 | Q10: 0 | R10: 12 | S10: 12 | T10: 12 | U10: 12 | V10: 0 | W10: 0 | X10: 12 | Y10: 12 | Z10: 12 | AA10: 12 | AB10: 0 | AC10: 0 | AD10: 6 | AE10: 12 | AF10: 12 | AG10: 12 | AH10: 0 | AI10: 0 | AJ10: 12 | AK10: 12 | AL10: 12 | AM10: 12 | AN10: 0 | AO10: 0 | AP10: 12
A11: 刘昕 | B11: 前厅 | C11: 前台 | G11: 3500 | H11: 3500 | I11: 0 | J11: 0 | K11: 20
A12: 邹璇 | B12: 前厅 | C12: 前台 | G12: 3500 | H12: 3500 | I12: 0 | J12: 0 | K12: 26 | L12: 8 | M12: 8 | N12: 8 | O12: 8 | P12: 8 | Q12: 8 | R12: 0 | S12: 8 | T12: 8 | U12: 8 | V12: 8 | W12: 8 | X12: 8 | Y12: 0 | Z12: 12 | AA12: 12 | AB12: 0 | AC12: 8 | AD12: 8 | AE12: 8 | AF12: 8 | AG12: 8 | AH12: 12 | AI12: 12 | AJ12: 0 | AK12: 0 | AL12: 12 | AM12: 12 | AN12: 12 | AO12: 12 | AP12: 0
A16: 前台工时 | L16: =SUM(L2:L15) -> 72 | M16: =SUM(M2:M15) -> 72 | N16: =SUM(N2:N15) -> 68 | O16: =SUM(O2:O15) -> 60 | P16: =SUM(P2:P15) -> 80 | Q16: =SUM(Q2:Q15) -> 80 | R16: =SUM(R2:R15) -> 72 | S16: =SUM(S2:S15) -> 80 | ... AP16: =SUM(AP2:AP15) -> 68

Sheet 前台增值物品出入库录入
B1: 前台增值物品出入库表
B2: 酒店名称： | N2: 周期：
A3: 序号 | B3: 货品名称 | C3: 规格型号 | D3: 单位 | E3: 单价 | F3: 上月 结存 | G3: 结存金额 | H3: 入库合计 | I3: 入库金额 | J3: 出库合计 | K3: 出库金额 | L3: 结存合计 | M3: 结存金额 | N3: 1号 | P3: 2号 | R3: 3号 | T3: 4号 | V3: 5号 | X3: 6号 | Z3: 7号 | AB3: 8号 | AD3: 9号 | AF3: 10号 | AH3: 11号 | AJ3: 12号 | AL3: 13号 | AN3: 14号 | AP3: 15号 | AR3: 16号 | AT3: 17号 | AV3: 18号 | AX3: 19号 | AZ3: 20号 | BB3: 21号 | BD3: 22号 | BF3: 23号 | BH3: 24号 | BJ3: 25号 | BL3: 26号 | BN3: 27号 | BP3: 28号 | BR3: 29号 | BT3: 30号 | BV3: 31号
H4: 入库 | J4: 出库 | N4: 入库 | O4: 出库 | P4: 入库 | Q4: 出库 | R4: 入库 | S4: 出库 | T4: 入库 | U4: 出库 | V4: 入库 | W4: 出库 | X4: 入库 | Y4: 出库 | Z4: 入库 | AA4: 出库 | AB4: 入库 | AC4: 出库 | AD4: 入库 | AE4: 出库 | AF4: 入库 | AG4: 出库 | AH4: 入库 | AI4: 出库 | AJ4: 入库 | AK4: 出库 | AL4: 入库 | AM4: 出库 | AN4: 入库 | AO4: 出库 | AP4: 入库 | AQ4: 出库 | AR4: 入库 | AS4: 出库 | AT4: 入库 | AU4: 出库 | AV4: 入库 | AW4: 出库 | AX4: 入库 | AY4: 出库 | AZ4: 入库 | BA4: 出库 | BB4: 入库 | BC4: 出库 | BD4: 入库 | BE4: 出库 | BF4: 入库 | BG4: 出库 | BH4: 入库 | BI4: 出库 | BJ4: 入库 | BK4: 出库 | BL4: 入库 | BM4: 出库 | BN4: 入库 | BO4: 出库 | BP4: 入库 | BQ4: 出库 | BR4: 入库 | BS4: 出库 | BT4: 入库 | BU4: 出库 | BV4: 入库 | BW4: 出库
A5: 1 | B5: 剃须刀 | D5: 个 | E5: 1.2 | F5: 0 | G5: =F5*E5 -> 0 | H5: =SUMIF($N$4:$BW$4,$H$4,$N5:$BW5) -> 0 | I5: =+E5*H5 -> 0 | J5: =SUMIF($N$4:$BW$4,$J$4,$N5:$BW5) -> 0 | K5: =+E5*J5 -> 0 | L5: =+F5+H5-J5 -> 0 | M5: =+E5*L5 -> 0
A6: 2 | B6: 费用报销单 | D6: 个 | E6: 2 | F6: 5 | G6: =F6*E6 -> 10 | H6: =SUMIF($N$4:$BW$4,$H$4,$N6:$BW6) -> 0 | I6: =+E6*H6 -> 0 | J6: =SUMIF($N$4:$BW$4,$J$4,$N6:$BW6) -> 0 | K6: =+E6*J6 -> 0 | L6: =+F6+H6-J6 -> 5 | M6: =+E6*L6 -> 10
A7: 3 | B7: 记号笔 | D7: 个 | E7: 0.398 | F7: 35 | G7: =F7*E7 -> 13.93 | H7: =SUMIF($N$4:$BW$4,$H$4,$N7:$BW7) -> 0 | I7: =+E7*H7 -> 0 | J7: =SUMIF($N$4:$BW$4,$J$4,$N7:$BW7) -> 4 | K7: =+E7*J7 -> 1.592 | L7: =+F7+H7-J7 -> 31 | M7: =+E7*L7 -> 12.338 | O7: 1 | BK7: 3
A8: 4 | B8: 前台交接本 | D8: 个 | E8: 7 | F8: 27 | G8: =F8*E8 -> 189 | H8: =SUMIF($N$4:$BW$4,$H$4,$N8:$BW8) -> 0 | I8: =+E8*H8 -> 0 | J8: =SUMIF($N$4:$BW$4,$J$4,$N8:$BW8) -> 2 | K8: =+E8*J8 -> 14 | L8: =+F8+H8-J8 -> 25 | M8: =+E8*L8 -> 175 | O8: 1 | BK8: 1
A9: 5 | B9: 遗留物品登记表 | D9: 个 | E9: 7 | F9: 4 | G9: =F9*E9 -> 28 | H9: =SUMIF($N$4:$BW$4,$H$4,$N9:$BW9) -> 0 | I9: =+E9*H9 -> 0 | J9: =SUMIF($N$4:$BW$4,$J$4,$N9:$BW9) -> 0 | K9: =+E9*J9 -> 0 | L9: =+F9+H9-J9 -> 4 | M9: =+E9*L9 -> 28
A10: 6 | B10: 前台预抵本 | D10: 个 | E10: 7 | F10: 11 | G10: =F10*E10 -> 77 | H10: =SUMIF($N$4:$BW$4,$H$4,$N10:$BW10) -> 0 | I10: =+E10*H10 -> 0 | J10: =SUMIF($N$4:$BW$4,$J$4,$N10:$BW10) -> 0 | K10: =+E10*J10 -> 0 | L10: =+F10+H10-J10 -> 11 | M10: =+E10*L10 -> 77
A11: 7 | B11: 会议记录表 | D11: 个 | E11: 7 | F11: 15 | G11: =F11*E11 -> 105 | H11: =SUMIF($N$4:$BW$4,$H$4,$N11:$BW11) -> 0 | I11: =+E11*H11 -> 0 | J11: =SUMIF($N$4:$BW$4,$J$4,$N11:$BW11) -> 0 | K11: =+E11*J11 -> 0 | L11: =+F11+H11-J11 -> 15 | M11: =+E11*L11 -> 105
A12: 8 | B12: A4纸2 | D12: 张 | E12: 0.0354 | F12: 300 | G12: =F12*E12 -> 10.62 | H12: =SUMIF($N$4:$BW$4,$H$4,$N12:$BW12) -> 0 | I12: =+E12*H12 -> 0 | J12: =SUMIF($N$4:$BW$4,$J$4,$N12:$BW12) -> 300 | K12: =+E12*J12 -> 10.62 | L12: =+F12+H12-J12 -> 0 | M12: =+E12*L12 -> 0 | O12: 100 | AM12: 100 | AS12: 100
A13: 9 | B13: 纸碟子 | D13: 个 | E13: 0.06384 | F13: 360 | G13: =F13*E13 -> 22.9824 | H13: =SUMIF($N$4:$BW$4,$H$4,$N13:$BW13) -> 0 | I13: =+E13*H13 -> 0 | J13: =SUMIF($N$4:$BW$4,$J$4,$N13:$BW13) -> 360 | K13: =+E13*J13 -> 22.9824 | L13: =+F13+H13-J13 -> 0 | M13: =+E13*L13 -> 0 | O13: 20 | Q13: 20 | S13: 20 | U13: 20 | W13: 20 | AA13: 20 | AE13: 20 | AG13: 20 | AK13: 20 | BK13: 180
A14: 10 | B14: 口罩 | D14: 个 | E14: 0.115 | F14: 199 | G14: =F14*E14 -> 22.885 | H14: =SUMIF($N$4:$BW$4,$H$4,$N14:$BW14) -> 0 | I14: =+E14*H14 -> 0 | J14: =SUMIF($N$4:$BW$4,$J$4,$N14:$BW14) -> 57 | K14: =+E14*J14 -> 6.555 | L14: =+F14+H14-J14 -> 142 | M14: =+E14*L14 -> 16.33 | O14: 5 | S14: 6 | W14: 5 | AM14: 15 | AQ14: 10 | BK14: 2 | BM14: 2 | BO14: 1 | BS14: 1 | BU14: 5 | BW14: 5
A15: 11 | B15: 文件盒 | D15: 个 | E15: 4.495 | F15: 3 | G15: =F15*E15 -> 13.485 | H15: =SUMIF($N$4:$BW$4,$H$4,$N15:$BW15) -> 0 | I15: =+E15*H15 -> 0 | J15: =SUMIF($N$4:$BW$4,$J$4,$N15:$BW15) -> 2 | K15: =+E15*J15 -> 8.99 | L15: =+F15+H15-J15 -> 1 | M15: =+E15*L15 -> 4.495 | BG15: 1 | BM15: 1
A16: 12 | B16: 壁纸刀 | D16: 个 | E16: 3.495 | F16: 4 | G16: =F16*E16 -> 13.98 | H16: =SUMIF($N$4:$BW$4,$H$4,$N16:$BW16) -> 0 | I16: =+E16*H16 -> 0 | J16: =SUMIF($N$4:$BW$4,$J$4,$N16:$BW16) -> 4 | K16: =+E16*J16 -> 13.98 | L16: =+F16+H16-J16 -> 0 | M16: =+E16*L16 -> 0 | O16: 1 | BK16: 3
A17: 13 | B17: 铅笔 | D17: 个 | E17: 0.3779 | F17: 59 | G17: =F17*E17 -> 22.2961 | H17: =SUMIF($N$4:$BW$4,$H$4,$N17:$BW17) -> 0 | I17: =+E17*H17 -> 0 | J17: =SUMIF($N$4:$BW$4,$J$4,$N17:$BW17) -> 14 | K17: =+E17*J17 -> 5.2906 | L17: =+F17+H17-J17 -> 45 | M17: =+E17*L17 -> 17.0055 | AS17: 5 | BS17: 1 | BU17: 6 | BW17: 2
A18: 14 | B18: 拖把 | D18: 个 | E18: 29.6 | F18: 0 | G18: =F18*E18 -> 0 | H18: =SUMIF($N$4:$BW$4,$H$4,$N18:$BW18) -> 1 | I18: =+E18*H18 -> 29.6 | J18: =SUMIF($N$4:$BW$4,$J$4,$N18:$BW18) -> 1 | K18: =+E18*J18 -> 29.6 | L18: =+F18+H18-J18 -> 0 | M18: =+E18*L18 -> 0 | V18: 1 | BI18: 1
A19: 15 | B19: 削笔刀 | D19: 个 | E19: 9.5 | F19: 2 | G19: =F19*E19 -> 19 | H19: =SUMIF($N$4:$BW$4,$H$4,$N19:$BW19) -> 0 | I19: =+E19*H19 -> 0 | J19: =SUMIF($N$4:$BW$4,$J$4,$N19:$BW19) -> 0 | K19: =+E19*J19 -> 0 | L19: =+F19+H19-J19 -> 2 | M19: =+E19*L19 -> 19
A20: 70 | B20: 橡皮筋 | D20: 个 | E20: 0.28 | F20: 110 | G20: =F20*E20 -> 30.8 | H20: =SUMIF($N$4:$BW$4,$H$4,$N20:$BW20) -> 0 | I20: =+E20*H20 -> 0 | J20: =SUMIF($N$4:$BW$4,$J$4,$N20:$BW20) -> 60 | K20: =+E20*J20 -> 16.8 | L20: =+F20+H20-J20 -> 50 | M20: =+E20*L20 -> 14 | AQ20: 10 | AU20: 10 | AY20: 10 | BC20: 10 | BK20: 20
A21: 16 | B21: 茉莉花 | D21: 个 | E21: 19.9 | F21: 1 | G21: =F21*E21 -> 19.9 | H21: =SUMIF($N$4:$BW$4,$H$4,$N21:$BW21) -> 0 | I21: =+E21*H21 -> 0 | J21: =SUMIF($N$4:$BW$4,$J$4,$N21:$BW21) -> 1 | K21: =+E21*J21 -> 19.9 | L21: =+F21+H21-J21 -> 0 | M21: =+E21*L21 -> 0 | O21: 1
A22: 18 | B22: 中性笔 | D22: 个 | E22: 1.0605556 | F22: 26 | G22: =F22*E22 -> 27.574444 | H22: =SUMIF($N$4:$BW$4,$H$4,$N22:$BW22) -> 0 | I22: =+E22*H22 -> 0 | J22: =SUMIF($N$4:$BW$4,$J$4,$N22:$BW22) -> 11 | K22: =+E22*J22 -> 11.666111 | L22: =+F22+H22-J22 -> 15 | M22: =+E22*L22 -> 15.908333 | BA22: 3 | BC22: 3 | BI22: 2 | BK22: 1 | BM22: 2
A23: 19 | B23: 标签纸 | D23: 个 | E23: 0.0653 | F23: 50 | G23: =F23*E23 -> 3.265 | H23: =SUMIF($N$4:$BW$4,$H$4,$N23:$BW23) -> 0 | I23: =+E23*H23 -> 0 | J23: =SUMIF($N$4:$BW$4,$J$4,$N23:$BW23) -> 22 | K23: =+E23*J23 -> 1.4366 | L23: =+F23+H23-J23 -> 28 | M23: =+E23*L23 -> 1.8284 | O23: 2 | AU23: 5 | AW23: 3 | AY23: 10 | BK23: 2
A24: 20 | B24: 订书机 | D24: 个 | E24: 3.31 | F24: 1 | G24: =F24*E24 -> 3.31 | H24: =SUMIF($N$4:$BW$4,$H$4,$N24:$BW24) -> 0 | I24: =+E24*H24 -> 0 | J24: =SUMIF($N$4:$BW$4,$J$4,$N24:$BW24) -> 0 | K24: =+E24*J24 -> 0 | L24: =+F24+H24-J24 -> 1 | M24: =+E24*L24 -> 3.31
A25: 1 | B25: 订书钉 | D25: 个 | E25: 3.31 | F25: 8 | G25: =F25*E25 -> 26.48 | H25: =SUMIF($N$4:$BW$4,$H$4,$N25:$BW25) -> 0 | I25: =+E25*H25 -> 0 | J25: =SUMIF($N$4:$BW$4,$J$4,$N25:$BW25) -> 0 | K25: =+E25*J25 -> 0 | L25: =+F25+H25-J25 -> 8 | M25: =+E25*L25 -> 26.48
A26: 24 | B26: 固体胶 | D26: 个 | E26: 1.9916667 | F26: 4 | G26: =F26*E26 -> 7.9666667 | H26: =SUMIF($N$4:$BW$4,$H$4,$N26:$BW26) -> 0 | I26: =+E26*H26 -> 0 | J26: =SUMIF($N$4:$BW$4,$J$4,$N26:$BW26) -> 1 | K26: =+E26*J26 -> 1.9916667 | L26: =+F26+H26-J26 -> 3 | M26: =+E26*L26 -> 5.975 | Q26: 1
A27: 25 | B27: 棉签 | D27: 个 | E27: 0.01681875 | F27: 642 | G27: =F27*E27 -> 10.797638 | H27: =SUMIF($N$4:$BW$4,$H$4,$N27:$BW27) -> 0 | I27: =+E27*H27 -> 0 | J27: =SUMIF($N$4:$BW$4,$J$4,$N27:$BW27) -> 211 | K27: =+E27*J27 -> 3.5487562 | L27: =+F27+H27-J27 -> 431 | M27: =+E27*L27 -> 7.2488813 | Q27: 30 | S27: 15 | W27: 10 | AA27: 15 | AK27: 20 | AM27: 5 | AO27: 15 | AS27: 20 | AW27: 5 | AY27: 5 | BC27: 15 | BE27: 3 | BG27: 2 | BI27: 1 | BK27: 10 | BM27: 10 | BQ27: 5 | BS27: 10 | BU27: 15
A28: 26 | B28: 胶带+切割器 | D28: 个 | E28: 0.69567568 | F28: 15 | G28: =F28*E28 -> 10.435135 | H28: =SUMIF($N$4:$BW$4,$H$4,$N28:$BW28) -> 0 | I28: =+E28*H28 -> 0 | J28: =SUMIF($N$4:$BW$4,$J$4,$N28:$BW28) -> 0 | K28: =+E28*J28 -> 0 | L28: =+F28+H28-J28 -> 15 | M28: =+E28*L28 -> 10.435135
A29: 27 | B29: 回形针 | D29: 个 | E29: 0.0109 | F29: 1483 | G29: =F29*E29 -> 16.1647 | H29: =SUMIF($N$4:$BW$4,$H$4,$N29:$BW29) -> 0 | I29: =+E29*H29 -> 0 | J29: =SUMIF($N$4:$BW$4,$J$4,$N29:$BW29) -> 255 | K29: =+E29*J29 -> 2.7795 | L29: =+F29+H29-J29 -> 1228 | M29: =+E29*L29 -> 13.3852 | O29: 50 | Q29: 50 | W29: 30 | AY29: 30 | BC29: 20 | BE29: 20 | BM29: 30 | BQ29: 10 | BU29: 15
A30: 29 | B30: 卷尺子 | D30: 个 | E30: 1.5475 | F30: 0 | G30: =F30*E30 -> 0 | H30: =SUMIF($N$4:$BW$4,$H$4,$N30:$BW30) -> 0 | I30: =+E30*H30 -> 0 | J30: =SUMIF($N$4:$BW$4,$J$4,$N30:$BW30) -> 0 | K30: =+E30*J30 -> 0 | L30: =+F30+H30-J30 -> 0 | M30: =+E30*L30 -> 0
A31: 30 | B31: 便利贴 | D31: 个 | E31: 0.6915 | F31: 7 | G31: =F31*E31 -> 4.8405 | H31: =SUMIF($N$4:$BW$4,$H$4,$N31:$BW31) -> 0 | I31: =+E31*H31 -> 0 | J31: =SUMIF($N$4:$BW$4,$J$4,$N31:$BW31) -> 4 | K31: =+E31*J31 -> 2.766 | L31: =+F31+H31-J31 -> 3 | M31: =+E31*L31 -> 2.0745 | BA31: 2 | BE31: 1 | BM31: 1
A32: 31 | B32: A4透明袋 | D32: 个 | E32: 0.408 | F32: 98 | G32: =F32*E32 -> 39.984 | H32: =SUMIF($N$4:$BW$4,$H$4,$N32:$BW32) -> 0 | I32: =+E32*H32 -> 0 | J32: =SUMIF($N$4:$BW$4,$J$4,$N32:$BW32) -> 48 | K32: =+E32*J32 -> 19.584 | L32: =+F32+H32-J32 -> 50 | M32: =+E32*L32 -> 20.4 | O32: 20 | S32: 10 | W32: 5 | AA32: 5 | BC32: 4 | BG32: 4
A33: 32 | B33: 文件夹 | D33: 个 | E33: 4.9 | F33: 3 | G33: =F33*E33 -> 14.7 | H33: =SUMIF($N$4:$BW$4,$H$4,$N33:$BW33) -> 0 | I33: =+E33*H33 -> 0 | J33: =SUMIF($N$4:$BW$4,$J$4,$N33:$BW33) -> 0 | K33: =+E33*J33 -> 0 | L33: =+F33+H33-J33 -> 3 | M33: =+E33*L33 -> 14.7
A34: 33 | B34: 发绳2 | D34: 个 | E34: 0.0298 | F34: 0 | G34: =F34*E34 -> 0 | H34: =SUMIF($N$4:$BW$4,$H$4,$N34:$BW34) -> 500 | I34: =+E34*H34 -> 14.9 | J34: =SUMIF($N$4:$BW$4,$J$4,$N34:$BW34) -> 69 | K34: =+E34*J34 -> 2.0562 | L34: =+F34+H34-J34 -> 431 | M34: =+E34*L34 -> 12.8438 | V34: 500 | AO34: 5 | AQ34: 5 | AS34: 10 | BC34: 5 | BE34: 5 | BG34: 5 | BK34: 20 | BM34: 5 | BO34: 3 | BQ34: 4 | BS34: 2
A35: 34 | B35: 文件袋 | D35: 个 | E35: 2.64 | F35: 20 | G35: =F35*E35 -> 52.8 | H35: =SUMIF($N$4:$BW$4,$H$4,$N35:$BW35) -> 0 | I35: =+E35*H35 -> 0 | J35: =SUMIF($N$4:$BW$4,$J$4,$N35:$BW35) -> 0 | K35: =+E35*J35 -> 0 | L35: =+F35+H35-J35 -> 20 | M35: =+E35*L35 -> 52.8
A36: 35 | B36: 燕尾夹 | D36: 个 | E36: 0.632 | F36: 3 | G36: =F36*E36 -> 1.896 | H36: =SUMIF($N$4:$BW$4,$H$4,$N36:$BW36) -> 0 | I36: =+E36*H36 -> 0 | J36: =SUMIF($N$4:$BW$4,$J$4,$N36:$BW36) -> 3 | K36: =+E36*J36 -> 1.896 | L36: =+F36+H36-J36 -> 0 | M36: =+E36*L36 -> 0 | BC36: 3
A37: 36 | B37: 笔筒 | D37: 个 | E37: 2.9925 | F37: 2 | G37: =F37*E37 -> 5.985 | H37: =SUMIF($N$4:$BW$4,$H$4,$N37:$BW37) -> 0 | I37: =+E37*H37 -> 0 | J37: =SUMIF($N$4:$BW$4,$J$4,$N37:$BW37) -> 0 | K37: =+E37*J37 -> 0 | L37: =+F37+H37-J37 -> 2 | M37: =+E37*L37 -> 5.985
A38: 37 | B38: 酒精棉签 | D38: 个 | E38: 0.0798 | F38: 901 | G38: =F38*E38 -> 71.8998 | H38: =SUMIF($N$4:$BW$4,$H$4,$N38:$BW38) -> 0 | I38: =+E38*H38 -> 0 | J38: =SUMIF($N$4:$BW$4,$J$4,$N38:$BW38) -> 300 | K38: =+E38*J38 -> 23.94 | L38: =+F38+H38-J38 -> 601 | M38: =+E38*L38 -> 47.9598 | O38: 30 | S38: 15 | W38: 20 | AA38: 25 | AC38: 15 | AE38: 15 | AG38: 10 | AK38: 10 | AS38: 10 | AU38: 10 | AW38: 15 | AY38: 10 | BA38: 15 | BE38: 20 | BI38: 15 | BK38: 15 | BM38: 10 | BQ38: 15 | BS38: 5 | BU38: 10 | BW38: 10
A39: 38 | B39: 柠檬汁 | D39: 瓶 | E39: 29.335 | F39: 0 | G39: =F39*E39 -> 0 | H39: =SUMIF($N$4:$BW$4,$H$4,$N39:$BW39) -> 2 | I39: =+E39*H39 -> 58.67 | J39: =SUMIF($N$4:$BW$4,$J$4,$N39:$BW39) -> 2 | K39: =+E39*J39 -> 58.67 | L39: =+F39+H39-J39 -> 0 | M39: =+E39*L39 -> 0 | V39: 2 | W39: 1 | BK39: 1
A40: 39 | B40: 火柴4 | D40: 个 | E40: 0.2071 | F40: 450 | G40: =F40*E40 -> 93.195 | H40: =SUMIF($N$4:$BW$4,$H$4,$N40:$BW40) -> 0 | I40: =+E40*H40 -> 0 | J40: =SUMIF($N$4:$BW$4,$J$4,$N40:$BW40) -> 192 | K40: =+E40*J40 -> 39.7632 | L40: =+F40+H40-J40 -> 258 | M40: =+E40*L40 -> 53.4318 | O40: 50 | S40: 20 | W40: 15 | AA40: 10 | AE40: 5 | AI40: 5 | AK40: 5 | AM40: 5 | AO40: 10 | AQ40: 5 | AS40: 10 | AU40: 6 | AW40: 5 | BA40: 4 | BC40: 5 | BE40: 5 | BG40: 3 | BI40: 5 | BK40: 10 | BQ40: 5 | BS40: 3 | BU40: 1
...

Sheet 会员卡提成录入
B1: 前台会员卡提成明细
B2: 酒店名称：
A3: 序号 | B3: 人员姓名 | C3: 平台 | D3: 单位 | E3: 单价（根据实际情况填写） | G3: 出库金额 | H3: 1号 | I3: 2号 | J3: 3号 | K3: 4号 | L3: 5号 | M3: 6号 | N3: 7号 | O3: 8号 | P3: 9号 | Q3: 10号 | R3: 11号 | S3: 12号 | T3: 13号 | U3: 14号 | V3: 15号 | W3: 16号 | X3: 17号 | Y3: 18号 | Z3: 19号 | AA3: 20号 | AB3: 21号 | AC3: 22号 | AD3: 23号 | AE3: 24号 | AF3: 25号 | AG3: 26号 | AH3: 27号 | AI3: 28号 | AJ3: 29号 | AK3: 30号 | AL3: 31号
F4: 张数 | H4: 张数 | I4: 张数 | J4: 张数 | K4: 张数 | L4: 张数 | M4: 张数 | N4: 张数 | O4: 张数 | P4: 张数 | Q4: 张数 | R4: 张数 | S4: 张数 | T4: 张数 | U4: 张数 | V4: 张数 | W4: 张数 | X4: 张数 | Y4: 张数 | Z4: 张数 | AA4: 张数 | AB4: 张数 | AC4: 张数 | AD4: 张数 | AE4: 张数 | AF4: 张数 | AG4: 张数 | AH4: 张数 | AI4: 张数 | AJ4: 张数 | AK4: 张数 | AL4: 张数
A5: 1 | B5: 李龙梅 | C5: 金卡 | D5: 张 | E5: 11 | F5: =SUMIF($H$4:$AL$4,$F$4,$H5:$AL5) -> 0 | G5: =+E5*F5 -> 0
A6: 2 | B6: 李龙梅 | C6: 银卡 | D6: 张 | E6: 5 | F6: =SUMIF($H$4:$AL$4,$F$4,$H6:$AL6) -> 1 | G6: =+E6*F6 -> 5 | O6: 1
A7: 3 | B7: 李龙梅 | C7: 白金卡 | D7: 张 | E7: 20 | F7: =SUMIF($H$4:$AL$4,$F$4,$H7:$AL7) -> 0 | G7: =+E7*F7 -> 0
A8: 4 | B8: 王增 | C8: 金卡 | D8: 张 | E8: 11 | F8: =SUMIF($H$4:$AL$4,$F$4,$H8:$AL8) -> 20 | G8: =+E8*F8 -> 220 | L8: 4 | N8: 1 | R8: 2 | S8: 2 | Y8: 1 | AD8: 1 | AE8: 2 | AG8: 1 | AK8: 2 | AL8: 4
A9: 5 | B9: 王增 | C9: 银卡 | D9: 张 | E9: 5 | F9: =SUMIF($H$4:$AL$4,$F$4,$H9:$AL9) -> 25 | G9: =+E9*F9 -> 125 | L9: 1 | N9: 3 | O9: 1 | Q9: 1 | R9: 3 | S9: 2 | U9: 1 | V9: 3 | X9: 4 | Y9: 1 | AA9: 1 | AD9: 1 | AH9: 1 | AK9: 2
A10: 5 | B10: 王增 | C10: 白金卡 | D10: 张 | E10: 20 | F10: =SUMIF($H$4:$AL$4,$F$4,$H10:$AL10) -> 1 | G10: =+E10*F10 -> 20 | AA10: 1
A11: 5 | B11: 翟芮瑶 | C11: 金卡 | D11: 张 | E11: 11 | F11: =SUMIF($H$4:$AL$4,$F$4,$H11:$AL11) -> 9 | G11: =+E11*F11 -> 99 | K11: 2 | Q11: 1 | W11: 2 | AC11: 2 | AI11: 1 | AJ11: 1
A12: 5 | B12: 翟芮瑶 | C12: 银卡 | D12: 张 | E12: 5 | F12: =SUMIF($H$4:$AL$4,$F$4,$H12:$AL12) -> 11 | G12: =+E12*F12 -> 55 | K12: 2 | P12: 2 | Q12: 1 | AB12: 1 | AD12: 2 | AE12: 1 | AI12: 2
A13: 9 | B13: 翟芮瑶 | C13: 白金卡 | D13: 张 | E13: 20 | F13: =SUMIF($H$4:$AL$4,$F$4,$H13:$AL13) -> 1 | G13: =+E13*F13 -> 20 | Q13: 1
A14: 10 | B14: 孙源 | C14: 金卡 | D14: 张 | E14: 11 | F14: =SUMIF($H$4:$AL$4,$F$4,$H14:$AL14) -> 7 | G14: =+E14*F14 -> 77 | H14: 1 | J14: 2 | L14: 1 | N14: 1 | AK14: 2
A15: 11 | B15: 孙源 | C15: 银卡 | D15: 张 | E15: 5 | F15: =SUMIF($H$4:$AL$4,$F$4,$H15:$AL15) -> 12 | G15: =+E15*F15 -> 60 | M15: 1 | P15: 4 | T15: 1 | V15: 3 | AB15: 3
A16: 12 | B16: 孙源 | C16: 白金卡 | D16: 张 | E16: 20 | F16: =SUMIF($H$4:$AL$4,$F$4,$H16:$AL16) -> 0 | G16: =+E16*F16 -> 0
A17: 13 | B17: 张馨月 | C17: 金卡 | D17: 张 | E17: 11 | F17: =SUMIF($H$4:$AL$4,$F$4,$H17:$AL17) -> 3 | G17: =+E17*F17 -> 33 | O17: 2 | X17: 1
A18: 14 | B18: 张馨月 | C18: 银卡 | D18: 张 | E18: 5 | F18: =SUMIF($H$4:$AL$4,$F$4,$H18:$AL18) -> 5 | G18: =+E18*F18 -> 25 | K18: 1 | N18: 1 | Q18: 1 | AG18: 1 | AJ18: 1
A19: 15 | B19: 张馨月 | C19: 白金卡 | D19: 张 | E19: 20 | F19: =SUMIF($H$4:$AL$4,$F$4,$H19:$AL19) -> 0 | G19: =+E19*F19 -> 0
A20: 16 | B20: 宋雨霏 | C20: 金卡 | D20: 张 | E20: 11 | F20: =SUMIF($H$4:$AL$4,$F$4,$H20:$AL20) -> 0 | G20: =+E20*F20 -> 0
A21: 17 | B21: 宋雨霏 | C21: 银卡 | D21: 张 | E21: 5 | F21: =SUMIF($H$4:$AL$4,$F$4,$H21:$AL21) -> 0 | G21: =+E21*F21 -> 0
A22: 18 | B22: 宋雨霏 | C22: 白金卡 | D22: 张 | E22: 20 | F22: =SUMIF($H$4:$AL$4,$F$4,$H22:$AL22) -> 1 | G22: =+E22*F22 -> 20 | I22: 1
A23: 19 | B23: 于子杭 | C23: 金卡 | D23: 张 | E23: 11 | F23: =SUMIF($H$4:$AL$4,$F$4,$H23:$AL23) -> 1 | G23: =+E23*F23 -> 11 | V23: 1
A24: 20 | B24: 于子杭 | C24: 银卡 | D24: 张 | E24: 5 | F24: =SUMIF($H$4:$AL$4,$F$4,$H24:$AL24) -> 1 | G24: =+E24*F24 -> 5 | AL24: 1
A25: 21 | B25: 于子杭 | C25: 白金卡 | D25: 张 | E25: 20 | F25: =SUMIF($H$4:$AL$4,$F$4,$H25:$AL25) -> 1 | G25: =+E25*F25 -> 20 | W25: 1
A26: 22 | B26: 徐嘉瑜 | C26: 金卡 | D26: 张 | E26: 11 | F26: =SUMIF($H$4:$AL$4,$F$4,$H26:$AL26) -> 5 | G26: =+E26*F26 -> 55 | N26: 1 | O26: 1 | U26: 1 | AC26: 1 | AF26: 1
A27: 23 | B27: 徐嘉瑜 | C27: 银卡 | D27: 张 | E27: 5 | F27: =SUMIF($H$4:$AL$4,$F$4,$H27:$AL27) -> 9 | G27: =+E27*F27 -> 45 | O27: 3 | P27: 1 | Z27: 1 | AF27: 1 | AL27: 3
A28: 24 | B28: 徐嘉瑜 | C28: 白金卡 | D28: 张 | E28: 20 | F28: =SUMIF($H$4:$AL$4,$F$4,$H28:$AL28) -> 0 | G28: =+E28*F28 -> 0
A29: 25 | B29: 吴怡 | C29: 金卡 | D29: 张 | E29: 11 | F29: =SUMIF($H$4:$AL$4,$F$4,$H29:$AL29) -> 2 | G29: =+E29*F29 -> 22 | W29: 1 | AG29: 1
A30: 26 | B30: 吴怡 | C30: 银卡 | D30: 张 | E30: 5 | F30: =SUMIF($H$4:$AL$4,$F$4,$H30:$AL30) -> 8 | G30: =+E30*F30 -> 40 | H30: 2 | K30: 1 | Q30: 2 | T30: 1 | AA30: 1 | AL30: 1
A31: 27 | B31: 吴怡 | C31: 白金卡 | D31: 张 | E31: 20 | F31: =SUMIF($H$4:$AL$4,$F$4,$H31:$AL31) -> 0 | G31: =+E31*F31 -> 0
A32: 28 | B32: 刘昕 | C32: 金卡 | D32: 张 | E32: 11 | F32: =SUMIF($H$4:$AL$4,$F$4,$H32:$AL32) -> 0 | G32: =+E32*F32 -> 0
A33: 29 | B33: 刘昕 | C33: 银卡 | D33: 张 | E33: 5 | F33: =SUMIF($H$4:$AL$4,$F$4,$H33:$AL33) -> 0 | G33: =+E33*F33 -> 0
A34: 30 | B34: 刘昕 | C34: 白金卡 | D34: 张 | E34: 20 | F34: =SUMIF($H$4:$AL$4,$F$4,$H34:$AL34) -> 0 | G34: =+E34*F34 -> 0
A35: 31 | F35: =SUMIF($H$4:$AL$4,$F$4,$H35:$AL35) -> 0 | G35: =+E35*F35 -> 0
A36: 32 | F36: =SUMIF($H$4:$AL$4,$F$4,$H36:$AL36) -> 0 | G36: =+E36*F36 -> 0
A37: 33 | F37: =SUMIF($H$4:$AL$4,$F$4,$H37:$AL37) -> 0 | G37: =+E37*F37 -> 0
A38: 34 | F38: =SUMIF($H$4:$AL$4,$F$4,$H38:$AL38) -> 0 | G38: =+E38*F38 -> 0
A39: 35 | F39: =SUMIF($H$4:$AL$4,$F$4,$H39:$AL39) -> 0 | G39: =+E39*F39 -> 0
A40: 36 | F40: =SUMIF($H$4:$AL$4,$F$4,$H40:$AL40) -> 0 | G40: =+E40*F40 -> 0
...

Sheet 商品录入
B1: 前台小商品出入库表
B2: 酒店名称： | N2: 周期：
A3: 序号 | B3: 货品名称 | C3: 规格型号 | D3: 单位 | E3: 单价 | F3: 上月 结存 | G3: 结存金额 | H3: 入库合计 | I3: 入库金额 | J3: 出库合计 | K3: 出库金额 | L3: 结存合计 | M3: 结存金额 | N3: 1号 | P3: 2号 | R3: 3号 | T3: 4号 | V3: 5号 | X3: 6号 | Z3: 7号 | AB3: 8号 | AD3: 9号 | AF3: 10号 | AH3: 11号 | AJ3: 12号 | AL3: 13号 | AN3: 14号 | AP3: 15号 | AR3: 16号 | AT3: 17号 | AV3: 18号 | AX3: 19号 | AZ3: 20号 | BB3: 21号 | BD3: 22号 | BF3: 23号 | BH3: 24号 | BJ3: 25号 | BL3: 26号 | BN3: 27号 | BP3: 28号 | BR3: 29号 | BT3: 30号 | BV3: 31号
H4: 入库 | I4: 金额 | J4: 出库 | L4: 结存 | N4: 入库 | O4: 出库 | P4: 入库 | Q4: 出库 | R4: 入库 | S4: 出库 | T4: 入库 | U4: 出库 | V4: 入库 | W4: 出库 | X4: 入库 | Y4: 出库 | Z4: 入库 | AA4: 出库 | AB4: 入库 | AC4: 出库 | AD4: 入库 | AE4: 出库 | AF4: 入库 | AG4: 出库 | AH4: 入库 | AI4: 出库 | AJ4: 入库 | AK4: 出库 | AL4: 入库 | AM4: 出库 | AN4: 入库 | AO4: 出库 | AP4: 入库 | AQ4: 出库 | AR4: 入库 | AS4: 出库 | AT4: 入库 | AU4: 出库 | AV4: 入库 | AW4: 出库 | AX4: 入库 | AY4: 出库 | AZ4: 入库 | BA4: 出库 | BB4: 入库 | BC4: 出库 | BD4: 入库 | BE4: 出库 | BF4: 入库 | BG4: 出库 | BH4: 入库 | BI4: 出库 | BJ4: 入库 | BK4: 出库 | BL4: 入库 | BM4: 出库 | BN4: 入库 | BO4: 出库 | BP4: 入库 | BQ4: 出库 | BR4: 入库 | BS4: 出库 | BT4: 入库 | BU4: 出库 | BV4: 入库 | BW4: 出库
A5: 1 | B5: 洗手液 | C5: 瓶 | E5: 7.9 | F5: 0 | G5: =F5*E5 -> 0 | H5: =SUMIF($N$4:$O$4,$H$4,$N5:$O5) -> 33 | I5: =+E5*H5 -> 260.7 | J5: =SUMIF($N$4:$BW$4,$J$4,$N5:$BW5) -> 1 | K5: =+E5*J5 -> 7.9 | L5: =+F5+H5-J5 -> 32 | M5: =+E5*L5 -> 252.8 | N5: 33 | Q5: 1
A6: 2 | B6: 洗发水 | C6: 瓶 | E6: 13.5 | F6: 0 | G6: =F6*E6 -> 0 | H6: =SUMIF($N$4:$O$4,$H$4,$N6:$O6) -> 27 | I6: =+E6*H6 -> 364.5 | J6: =SUMIF($N$4:$BW$4,$J$4,$N6:$BW6) -> 0 | K6: =+E6*J6 -> 0 | L6: =+F6+H6-J6 -> 27 | M6: =+E6*L6 -> 364.5 | N6: 27
A7: 3 | B7: 护发素 | C7: 瓶 | E7: 13.5 | F7: 0 | G7: =F7*E7 -> 0 | H7: =SUMIF($N$4:$O$4,$H$4,$N7:$O7) -> 28 | I7: =+E7*H7 -> 378 | J7: =SUMIF($N$4:$BW$4,$J$4,$N7:$BW7) -> 0 | K7: =+E7*J7 -> 0 | L7: =+F7+H7-J7 -> 28 | M7: =+E7*L7 -> 378 | N7: 28
A8: 4 | B8: 沐浴露 | C8: 瓶 | E8: 13.5 | F8: 0 | G8: =F8*E8 -> 0 | H8: =SUMIF($N$4:$O$4,$H$4,$N8:$O8) -> 30 | I8: =+E8*H8 -> 405 | J8: =SUMIF($N$4:$BW$4,$J$4,$N8:$BW8) -> 0 | K8: =+E8*J8 -> 0 | L8: =+F8+H8-J8 -> 30 | M8: =+E8*L8 -> 405 | N8: 30
A9: 5 | B9: 乳胶枕 | C9: 个 | E9: 66 | F9: 0 | G9: =F9*E9 -> 0 | H9: =SUMIF($N$4:$O$4,$H$4,$N9:$O9) -> 22 | I9: =+E9*H9 -> 1452 | J9: =SUMIF($N$4:$BW$4,$J$4,$N9:$BW9) -> 3 | K9: =+E9*J9 -> 198 | L9: =+F9+H9-J9 -> 19 | M9: =+E9*L9 -> 1254 | N9: 22 | AQ9: 1 | BA9: 2
A10: 6 | B10: 羽绒枕 | C10: 个 | E10: 113.5 | F10: 0 | G10: =F10*E10 -> 0 | H10: =SUMIF($N$4:$O$4,$H$4,$N10:$O10) -> 10 | I10: =+E10*H10 -> 1135 | J10: =SUMIF($N$4:$BW$4,$J$4,$N10:$BW10) -> 0 | K10: =+E10*J10 -> 0 | L10: =+F10+H10-J10 -> 10 | M10: =+E10*L10 -> 1135 | N10: 10
A11: 7 | B11: 香薰液 | C11: 瓶 | E11: 176 | F11: 0 | G11: =F11*E11 -> 0 | H11: =SUMIF($N$4:$O$4,$H$4,$N11:$O11) -> 9 | I11: =+E11*H11 -> 1584 | J11: =SUMIF($N$4:$BW$4,$J$4,$N11:$BW11) -> 0 | K11: =+E11*J11 -> 0 | L11: =+F11+H11-J11 -> 9 | M11: =+E11*L11 -> 1584 | N11: 9
A12: 8 | E12: 0 | F12: 0 | G12: =F12*E12 -> 0 | H12: =SUMIF($N$4:$O$4,$H$4,$N12:$O12) -> 0 | I12: =+E12*H12 -> 0 | J12: =SUMIF($N$4:$BW$4,$J$4,$N12:$BW12) -> 0 | K12: =+E12*J12 -> 0 | L12: =+F12+H12-J12 -> 0 | M12: =+E12*L12 -> 0
A13: 9 | E13: 0 | F13: 0 | G13: =F13*E13 -> 0 | H13: =SUMIF($N$4:$O$4,$H$4,$N13:$O13) -> 0 | I13: =+E13*H13 -> 0 | J13: =SUMIF($N$4:$BW$4,$J$4,$N13:$BW13) -> 0 | K13: =+E13*J13 -> 0 | L13: =+F13+H13-J13 -> 0 | M13: =+E13*L13 -> 0
A14: 10 | E14: 0 | F14: 0 | G14: =F14*E14 -> 0 | H14: =SUMIF($N$4:$O$4,$H$4,$N14:$O14) -> 0 | I14: =+E14*H14 -> 0 | J14: =SUMIF($N$4:$BW$4,$J$4,$N14:$BW14) -> 0 | K14: =+E14*J14 -> 0 | L14: =+F14+H14-J14 -> 0 | M14: =+E14*L14 -> 0
A15: 11 | E15: 0 | F15: 0 | G15: =F15*E15 -> 0 | H15: =SUMIF($N$4:$O$4,$H$4,$N15:$O15) -> 0 | I15: =+E15*H15 -> 0 | J15: =SUMIF($N$4:$BW$4,$J$4,$N15:$BW15) -> 0 | K15: =+E15*J15 -> 0 | L15: =+F15+H15-J15 -> 0 | M15: =+E15*L15 -> 0
A16: 12 | E16: 0 | F16: 0 | G16: =F16*E16 -> 0 | H16: =SUMIF($N$4:$O$4,$H$4,$N16:$O16) -> 0 | I16: =+E16*H16 -> 0 | J16: =SUMIF($N$4:$BW$4,$J$4,$N16:$BW16) -> 0 | K16: =+E16*J16 -> 0 | L16: =+F16+H16-J16 -> 0 | M16: =+E16*L16 -> 0
A17: 13 | E17: 0 | F17: 0 | G17: =F17*E17 -> 0 | H17: =SUMIF($N$4:$O$4,$H$4,$N17:$O17) -> 0 | I17: =+E17*H17 -> 0 | J17: =SUMIF($N$4:$BW$4,$J$4,$N17:$BW17) -> 0 | K17: =+E17*J17 -> 0 | L17: =+F17+H17-J17 -> 0 | M17: =+E17*L17 -> 0
A18: 14 | E18: 0 | F18: 0 | G18: =F18*E18 -> 0 | H18: =SUMIF($N$4:$O$4,$H$4,$N18:$O18) -> 0 | I18: =+E18*H18 -> 0 | J18: =SUMIF($N$4:$BW$4,$J$4,$N18:$BW18) -> 0 | K18: =+E18*J18 -> 0 | L18: =+F18+H18-J18 -> 0 | M18: =+E18*L18 -> 0
A19: 15 | E19: 0 | F19: 0 | G19: =F19*E19 -> 0 | H19: =SUMIF($N$4:$O$4,$H$4,$N19:$O19) -> 0 | I19: =+E19*H19 -> 0 | J19: =SUMIF($N$4:$BW$4,$J$4,$N19:$BW19) -> 0 | K19: =+E19*J19 -> 0 | L19: =+F19+H19-J19 -> 0 | M19: =+E19*L19 -> 0
A20: 16 | E20: 0 | F20: 0 | G20: =F20*E20 -> 0 | H20: =SUMIF($N$4:$O$4,$H$4,$N20:$O20) -> 0 | I20: =+E20*H20 -> 0 | J20: =SUMIF($N$4:$BW$4,$J$4,$N20:$BW20) -> 0 | K20: =+E20*J20 -> 0 | L20: =+F20+H20-J20 -> 0 | M20: =+E20*L20 -> 0
A21: 17 | E21: 0 | F21: 0 | G21: =F21*E21 -> 0 | H21: =SUMIF($N$4:$O$4,$H$4,$N21:$O21) -> 0 | I21: =+E21*H21 -> 0 | J21: =SUMIF($N$4:$BW$4,$J$4,$N21:$BW21) -> 0 | K21: =+E21*J21 -> 0 | L21: =+F21+H21-J21 -> 0 | M21: =+E21*L21 -> 0
A22: 18 | F22: 0 | G22: =F22*E22 -> 0 | H22: =SUMIF($N$4:$O$4,$H$4,$N22:$O22) -> 0 | I22: =+E22*H22 -> 0 | J22: =SUMIF($N$4:$BW$4,$J$4,$N22:$BW22) -> 0 | K22: =+E22*J22 -> 0 | L22: =+F22+H22-J22 -> 0 | M22: =+E22*L22 -> 0
A23: 19 | F23: 0 | G23: =F23*E23 -> 0 | H23: =SUMIF($N$4:$O$4,$H$4,$N23:$O23) -> 0 | I23: =+E23*H23 -> 0 | J23: =SUMIF($N$4:$BW$4,$J$4,$N23:$BW23) -> 0 | K23: =+E23*J23 -> 0 | L23: =+F23+H23-J23 -> 0 | M23: =+E23*L23 -> 0
A24: 20 | F24: 0 | G24: =F24*E24 -> 0 | H24: =SUMIF($N$4:$O$4,$H$4,$N24:$O24) -> 0 | I24: =+E24*H24 -> 0 | J24: =SUMIF($N$4:$BW$4,$J$4,$N24:$BW24) -> 0 | K24: =+E24*J24 -> 0 | L24: 0 | M24: =+E24*L24 -> 0
A25: 21 | F25: 0 | G25: =F25*E25 -> 0 | H25: =SUMIF($N$4:$O$4,$H$4,$N25:$O25) -> 0 | I25: =+E25*H25 -> 0 | J25: =SUMIF($N$4:$BW$4,$J$4,$N25:$BW25) -> 0 | K25: =+E25*J25 -> 0 | L25: =+F25+H25-J25 -> 0 | M25: =+E25*L25 -> 0
A26: 22 | F26: 0 | G26: =F26*E26 -> 0 | H26: =SUMIF($N$4:$O$4,$H$4,$N26:$O26) -> 0 | I26: =+E26*H26 -> 0 | J26: =SUMIF($N$4:$BW$4,$J$4,$N26:$BW26) -> 0 | K26: =+E26*J26 -> 0 | L26: =+F26+H26-J26 -> 0 | M26: =+E26*L26 -> 0
A27: 23 | F27: 0 | G27: =F27*E27 -> 0 | H27: =SUMIF($N$4:$O$4,$H$4,$N27:$O27) -> 0 | I27: =+E27*H27 -> 0 | J27: =SUMIF($N$4:$BW$4,$J$4,$N27:$BW27) -> 0 | K27: =+E27*J27 -> 0 | L27: =+F27+H27-J27 -> 0 | M27: =+E27*L27 -> 0
A28: 24 | F28: 0 | G28: =F28*E28 -> 0 | H28: =SUMIF($N$4:$O$4,$H$4,$N28:$O28) -> 0 | I28: =+E28*H28 -> 0 | J28: =SUMIF($N$4:$BW$4,$J$4,$N28:$BW28) -> 0 | K28: =+E28*J28 -> 0 | L28: =+F28+H28-J28 -> 0 | M28: =+E28*L28 -> 0
A29: 25 | F29: 0 | G29: =F29*E29 -> 0 | H29: =SUMIF($N$4:$O$4,$H$4,$N29:$O29) -> 0 | I29: =+E29*H29 -> 0 | J29: =SUMIF($N$4:$BW$4,$J$4,$N29:$BW29) -> 0 | K29: =+E29*J29 -> 0 | L29: =+F29+H29-J29 -> 0 | M29: =+E29*L29 -> 0
A30: 26 | F30: 0 | G30: =F30*E30 -> 0 | H30: =SUMIF($N$4:$O$4,$H$4,$N30:$O30) -> 0 | I30: =+E30*H30 -> 0 | J30: =SUMIF($N$4:$BW$4,$J$4,$N30:$BW30) -> 0 | K30: =+E30*J30 -> 0 | L30: =+F30+H30-J30 -> 0 | M30: =+E30*L30 -> 0
A31: 27 | F31: 0 | G31: =F31*E31 -> 0 | H31: =SUMIF($N$4:$O$4,$H$4,$N31:$O31) -> 0 | I31: =+E31*H31 -> 0 | J31: =SUMIF($N$4:$BW$4,$J$4,$N31:$BW31) -> 0 | K31: =+E31*J31 -> 0 | L31: =+F31+H31-J31 -> 0 | M31: =+E31*L31 -> 0
A32: 28 | F32: 0 | G32: =F32*E32 -> 0 | H32: =SUMIF($N$4:$O$4,$H$4,$N32:$O32) -> 0 | I32: =+E32*H32 -> 0 | J32: =SUMIF($N$4:$BW$4,$J$4,$N32:$BW32) -> 0 | K32: =+E32*J32 -> 0 | L32: =+F32+H32-J32 -> 0 | M32: =+E32*L32 -> 0
A33: 29 | F33: 0 | G33: =F33*E33 -> 0 | H33: =SUMIF($N$4:$O$4,$H$4,$N33:$O33) -> 0 | I33: =+E33*H33 -> 0 | J33: =SUMIF($N$4:$BW$4,$J$4,$N33:$BW33) -> 0 | K33: =+E33*J33 -> 0 | L33: =+F33+H33-J33 -> 0 | M33: =+E33*L33 -> 0
A34: 30 | F34: 0 | G34: =F34*E34 -> 0 | H34: =SUMIF($N$4:$O$4,$H$4,$N34:$O34) -> 0 | I34: =+E34*H34 -> 0 | J34: =SUMIF($N$4:$BW$4,$J$4,$N34:$BW34) -> 0 | K34: =+E34*J34 -> 0 | L34: =+F34+H34-J34 -> 0 | M34: =+E34*L34 -> 0
A35: 31 | F35: 0 | G35: =F35*E35 -> 0 | H35: =SUMIF($N$4:$O$4,$H$4,$N35:$O35) -> 0 | I35: =+E35*H35 -> 0 | J35: =SUMIF($N$4:$BW$4,$J$4,$N35:$BW35) -> 0 | K35: =+E35*J35 -> 0 | L35: =+F35+H35-J35 -> 0 | M35: =+E35*L35 -> 0
A36: 32 | F36: 0 | G36: =F36*E36 -> 0 | H36: =SUMIF($N$4:$O$4,$H$4,$N36:$O36) -> 0 | I36: =+E36*H36 -> 0 | J36: =SUMIF($N$4:$BW$4,$J$4,$N36:$BW36) -> 0 | K36: =+E36*J36 -> 0 | L36: =+F36+H36-J36 -> 0 | M36: =+E36*L36 -> 0
... A42: 38 | F42: 0 | G42: =F42*E42 -> 0 | H42: =SUMIF($N$4:$O$4,$H$4,$N42:$O42) -> 0 | I42: =+E42*H42 -> 0 | J42: =SUMIF($N$4:$BW$4,$J$4,$N42:$BW42) -> 0 | K42: =+E42*J42 -> 0 | L42: =+F42+H42-J42 -> 0 | M42: =+E42*L42 -> 0
A43: 39 | F43: 0 | G43: =+E43*F43 -> 0 | H43: =SUMIF($N$4:$O$4,$H$4,$N43:$O43) -> 0 | I43: =+E43*H43 -> 0 | J43: =SUMIF($N$4:$BW$4,$J$4,$N43:$BW43) -> 0 | K43: =+E43*J43 -> 0 | L43: =+F43+H43-J43 -> 0 | M43: =+E43*L43 -> 0
A44: 40 | G44: =+E44*F44 -> 0 | H44: =SUMIF($N$4:$O$4,$H$4,$N44:$O44) -> 0 | I44: =+E44*H44 -> 0 | J44: =SUMIF($N$4:$BW$4,$J$4,$N44:$BW44) -> 0 | K44: =+E44*J44 -> 0 | L44: =+F44+H44-J44 -> 0 | M44: =+E44*L44 -> 0
A45: 41 | G45: =+E45*F45 -> 0 | H45: =SUMIF($N$4:$O$4,$H$4,$N45:$O45) -> 0 | I45: =+E45*H45 -> 0 | J45: =SUMIF($N$4:$BW$4,$J$4,$N45:$BW45) -> 0 | K45: =+E45*J45 -> 0 | L45: =+F45+H45-J45 -> 0 | M45: =+E45*L45 -> 0
...

Sheet 客房耗材出入库录入
B1: 客房耗材物品出入库表
B2: 酒店名称： | N2: 周期：
A3: 序号 | B3: 货品名称 | C3: 规格型号 | D3: 单位 | E3: 单价 | F3: 上月 结存 | G3: 结存金额 | H3: 入库合计 | I3: 入库金额 | J3: 出库合计 | K3: 出库金额 | L3: 结存合计 | M3: 结存金额 | N3: 1号 | O3: 1号 | P3: 2号 | Q3: 2号 | R3: 3号 | S3: 3号 | T3: 4号 | U3: 4号 | V3: 5号 | W3: 5号 | X3: 6号 | Y3: 6号 | Z3: 7号 | AA3: 7号 | AB3: 8号 | AC3: 8号 | AD3: 9号 | AE3: 9号 | AF3: 10号 | AG3: 10号 | AH3: 11号 | AI3: 11号 | AJ3: 12号 | AK3: 12号 | AL3: 13号 | AM3: 13号 | AN3: 14号 | AO3: 14号 | AP3: 15号 | AQ3: 15号 | AR3: 16号 | AS3: 16号 | AT3: 17号 | AU3: 17号 | AV3: 18号 | AW3: 18号 | AX3: 19号 | AY3: 19号 | AZ3: 20号 | BA3: 20号 | BB3: 21号 | BC3: 21号 | BD3: 22号 | BE3: 22号 | BF3: 23号 | BG3: 23号 | BH3: 24号 | BI3: 24号 | BJ3: 25号 | BK3: 25号 | BL3: 26号 | BM3: 26号 | BN3: 27号 | BO3: 27号 | BP3: 28号 | BQ3: 28号 | BR3: 29号 | BS3: 29号 | BT3: 30号 | BU3: 30号 | BV3: 31号 | BW3: 31号
H4: 入库 | J4: 出库 | N4: 入库 | O4: 出库 | P4: 入库 | Q4: 出库 | R4: 入库 | S4: 出库 | T4: 入库 | U4: 出库 | V4: 入库 | W4: 出库 | X4: 入库 | Y4: 出库 | Z4: 入库 | AA4: 出库 | AB4: 入库 | AC4: 出库 | AD4: 入库 | AE4: 出库 | AF4: 入库 | AG4: 出库 | AH4: 入库 | AI4: 出库 | AJ4: 入库 | AK4: 出库 | AL4: 入库 | AM4: 出库 | AN4: 入库 | AO4: 出库 | AP4: 入库 | AQ4: 出库 | AR4: 入库 | AS4: 出库 | AT4: 入库 | AU4: 出库 | AV4: 入库 | AW4: 出库 | AX4: 入库 | AY4: 出库 | AZ4: 入库 | BA4: 出库 | BB4: 入库 | BC4: 出库 | BD4: 入库 | BE4: 出库 | BF4: 入库 | BG4: 出库 | BH4: 入库 | BI4: 出库 | BJ4: 入库 | BK4: 出库 | BL4: 入库 | BM4: 出库 | BN4: 入库 | BO4: 出库 | BP4: 入库 | BQ4: 出库 | BR4: 入库 | BS4: 出库 | BT4: 入库 | BU4: 出库 | BV4: 入库 | BW4: 出库
A5: 1 | B5: 牙刷 | D5: 支 | E5: 0.39 | F5: 5400 | G5: =F5*E5 -> 2106 | H5: =SUMIF($N$4:$BW$4,$H$4,$N5:$BW5) -> 0 | I5: =+E5*H5 -> 0 | J5: =SUMIF($N$4:$BW$4,$J$4,N5:$BW5) -> 3784 | K5: =+E5*J5 -> 1475.76 | L5: =+F5+H5-J5 -> 1616 | M5: =+E5*L5 -> 630.24 | O5: 98 | Q5: 106 | S5: 120 | U5: 102 | W5: 123 | Y5: 98 | AA5: 132 | AC5: 126 | AE5: 124 | AG5: 142 | AI5: 131 | AK5: 123 | AM5: 138 | AO5: 96 | AQ5: 119 | AS5: 123 | AU5: 114 | AW5: 120 | AY5: 116 | BA5: 127 | BC5: 122 | BE5: 118 | BG5: 123 | BI5: 119 | BK5: 132 | BM5: 118 | BO5: 120 | BQ5: 130 | BS5: 136 | BU5: 142 | BW5: 146
A6: 2 | B6: 牙膏 | D6: 支 | E6: 0.16 | F6: 6407 | G6: =F6*E6 -> 1025.12 | H6: =SUMIF($N$4:$BW$4,$H$4,$N6:$BW6) -> 0 | I6: =+E6*H6 -> 0 | J6: =SUMIF($N$4:$BW$4,$J$4,N6:$BW6) -> 3399 | K6: =+E6*J6 -> 543.84 | L6: =+F6+H6-J6 -> 3008 | M6: =+E6*L6 -> 481.28 | O6: 90 | Q6: 95 | S6: 113 | U6: 94 | W6: 106 | Y6: 88 | AA6: 112 | AC6: 118 | AE6: 105 | AG6: 127 | AI6: 118 | AK6: 108 | AM6: 124 | AO6: 88 | AQ6: 105 | AS6: 111 | AU6: 101 | AW6: 116 | AY6: 106 | BA6: 112 | BC6: 117 | BE6: 106 | BG6: 112 | BI6: 107 | BK6: 117 | BM6: 106 | BO6: 103 | BQ6: 114 | BS6: 124 | BU6: 126 | BW6: 130
A7: 3 | B7: 梳子 | D7: 把 | E7: 0.3 | F7: 3959 | G7: =F7*E7 -> 1187.7 | H7: =SUMIF($N$4:$BW$4,$H$4,$N7:$BW7) -> 0 | I7: =+E7*H7 -> 0 | J7: =SUMIF($N$4:$BW$4,$J$4,N7:$BW7) -> 2501 | K7: =+E7*J7 -> 750.3 | L7: =+F7+H7-J7 -> 1458 | M7: =+E7*L7 -> 437.4 | O7: 76 | Q7: 80 | S7: 85 | U7: 71 | W7: 78 | Y7: 88 | AA7: 68 | AC7: 80 | AE7: 78 | AG7: 92 | AI7: 88 | AK7: 82 | AM7: 90 | AO7: 52 | AQ7: 76 | AS7: 79 | AU7: 74 | AW7: 86 | AY7: 83 | BA7: 80 | BC7: 85 | BE7: 75 | BG7: 79 | BI7: 80 | BK7: 86 | BM7: 76 | BO7: 80 | BQ7: 86 | BS7: 92 | BU7: 86 | BW7: 90
A8: 4 | B8: 护理包 | D8: 包 | E8: 0.3 | F8: 4755 | G8: =F8*E8 -> 1426.5 | H8: =SUMIF($N$4:$BW$4,$H$4,$N8:$BW8) -> 0 | I8: =+E8*H8 -> 0 | J8: =SUMIF($N$4:$BW$4,$J$4,N8:$BW8) -> 2243 | K8: =+E8*J8 -> 672.9 | L8: =+F8+H8-J8 -> 2512 | M8: =+E8*L8 -> 753.6 | O8: 65 | Q8: 78 | S8: 75 | U8: 62 | W8: 78 | Y8: 79 | AA8: 65 | AC8: 75 | AE8: 69 | AG8: 73 | AI8: 68 | AK8: 70 | AM8: 72 | AO8: 50 | AQ8: 66 | AS8: 70 | AU8: 69 | AW8: 75 | AY8: 73 | BA8: 71 | BC8: 76 | BE8: 68 | BG8: 66 | BI8: 71 | BK8: 75 | BM8: 72 | BO8: 71 | BQ8: 84 | BS8: 84 | BU8: 87 | BW8: 86
A9: 5 | B9: 浴帽 | D9: 包 | E9: 0.21 | F9: 5900 | G9: =F9*E9 -> 1239 | H9: =SUMIF($N$4:$BW$4,$H$4,$N9:$BW9) -> 0 | I9: =+E9*H9 -> 0 | J9: =SUMIF($N$4:$BW$4,$J$4,N9:$BW9) -> 1912 | K9: =+E9*J9 -> 401.52 | L9: =+F9+H9-J9 -> 3988 | M9: =+E9*L9 -> 837.48 | O9: 50 | Q9: 66 | S9: 65 | U9: 53 | W9: 52 | Y9: 63 | AA9: 50 | AC9: 58 | AE9: 62 | AG9: 60 | AI9: 63 | AK9: 58 | AM9: 68 | AO9: 42 | AQ9: 54 | AS9: 61 | AU9: 58 | AW9: 63 | AY9: 64 | BA9: 68 | BC9: 60 | BE9: 62 | BG9: 65 | BI9: 63 | BK9: 68 | BM9: 63 | BO9: 62 | BQ9: 68 | BS9: 72 | BU9: 76 | BW9: 75
A10: 6 | B10: 拖鞋 | D10: 双 | E10: 1.59 | F10: 7546 | G10: =F10*E10 -> 11998.14 | H10: =SUMIF($N$4:$BW$4,$H$4,$N10:$BW10) -> 0 | I10: =+E10*H10 -> 0 | J10: =SUMIF($N$4:$BW$4,$J$4,N10:$BW10) -> 4101 | K10: =+E10*J10 -> 6520.59 | L10: =+F10+H10-J10 -> 3445 | M10: =+E10*L10 -> 5477.55 | O10: 114 | Q10: 122 | S10: 126 | U10: 118 | W10: 132 | Y10: 124 | AA10: 136 | AC10: 127 | AE10: 125 | AG10: 130 | AI10: 134 | AK10: 142 | AM10: 158 | AO10: 104 | AQ10: 128 | AS10: 135 | AU10: 122 | AW10: 139 | AY10: 127 | BA10: 137 | BC10: 132 | BE10: 125 | BG10: 134 | BI10: 129 | BK10: 136 | BM10: 121 | BO10: 126 | BQ10: 136 | BS10: 153 | BU10: 162 | BW10: 167
A11: 7 | B11: 儿童牙刷 | D11: 支 | E11: 1 | F11: 500 | G11: =F11*E11 -> 500 | H11: =SUMIF($N$4:$BW$4,$H$4,$N11:$BW11) -> 0 | I11: =+E11*H11 -> 0 | J11: =SUMIF($N$4:$BW$4,$J$4,N11:$BW11) -> 89 | K11: =+E11*J11 -> 89 | L11: =+F11+H11-J11 -> 411 | M11: =+E11*L11 -> 411 | O11: 1 | Q11: 4 | S11: 2 | U11: 2 | W11: 3 | AA11: 2 | AC11: 2 | AE11: 4 | AI11: 3 | AK11: 3 | AM11: 1 | AO11: 2 | AS11: 3 | AU11: 1 | AW11: 4 | AY11: 1 | BA11: 3 | BC11: 2 | BE11: 3 | BG11: 4 | BI11: 3 | BK11: 5 | BM11: 2 | BO11: 3 | BQ11: 5 | BS11: 6 | BU11: 7 | BW11: 8
A12: 8 | B12: 儿童拖鞋 | D12: 双 | E12: 1.8 | F12: 500 | G12: =F12*E12 -> 900 | H12: =SUMIF($N$4:$BW$4,$H$4,$N12:$BW12) -> 0 | I12: =+E12*H12 -> 0 | J12: =SUMIF($N$4:$BW$4,$J$4,N12:$BW12) -> 92 | K12: =+E12*J12 -> 165.6 | L12: =+F12+H12-J12 -> 408 | M12: =+E12*L12 -> 734.4 | O12: 1 | Q12: 4 | S12: 2 | U12: 2 | W12: 4 | AA12: 2 | AC12: 2 | AE12: 3 | AI12: 2 | AK12: 3 | AM12: 1 | AO12: 2 | AS12: 3 | AU12: 1 | AW12: 4 | AY12: 1 | BA12: 3 | BC12: 2 | BE12: 2 | BG12: 4 | BI12: 3 | BK12: 5 | BM12: 3 | BO12: 4 | BQ12: 6 | BS12: 8 | BU12: 7 | BW12: 8
A13: 9 | B13: 洗衣液 | D13: 瓶 | E13: 7.9 | F13: 21 | G13: =F13*E13 -> 165.9 | H13: =SUMIF($N$4:$BW$4,$H$4,$N13:$BW13) -> 0 | I13: =+E13*H13 -> 0 | J13: =SUMIF($N$4:$BW$4,$J$4,N13:$BW13) -> 11 | K13: =+E13*J13 -> 86.9 | L13: =+F13+H13-J13 -> 10 | M13: =+E13*L13 -> 79 | AA13: 1 | AE13: 1 | AO13: 1 | AU13: 1 | BA13: 1 | BG13: 1 | BO13: 1 | BQ13: 2 | BS13: 1 | BU13: 1
A14: 10 | B14: 洗手液 | D14: 瓶 | E14: 7.9 | F14: 83 | G14: =F14*E14 -> 655.7 | H14: =SUMIF($N$4:$BW$4,$H$4,$N14:$BW14) -> 0 | I14: =+E14*H14 -> 0 | J14: =SUMIF($N$4:$BW$4,$J$4,N14:$BW14) -> 28 | K14: =+E14*J14 -> 221.2 | L14: =+F14+H14-J14 -> 55 | M14: =+E14*L14 -> 434.5 | O14: 1 | Q14: 1 | S14: 1 | U14: 2 | W14: 1 | AA14: 1 | AE14: 2 | AG14: 1 | AI14: 1 | AM14: 2 | AO14: 1 | AS14: 1 | AW14: 1 | BA14: 1 | BC14: 2 | BE14: 2 | BI14: 1 | BK14: 1 | BO14: 2 | BS14: 1 | BW14: 2
A15: 11 | B15: 洗衣液补充液 | D15: 桶 | E15: 48 | F15: 23 | G15: =F15*E15 -> 1104 | H15: =SUMIF($N$4:$BW$4,$H$4,$N15:$BW15) -> 0 | I15: =+E15*H15 -> 0 | J15: =SUMIF($N$4:$BW$4,$J$4,N15:$BW15) -> 10 | K15: =+E15*J15 -> 480 | L15: =+F15+H15-J15 -> 13 | M15: =+E15*L15 -> 624 | S15: 1 | W15: 1 | AA15: 1 | AI15: 1 | AM15: 1 | AQ15: 1 | BA15: 1 | BG15: 1 | BS15: 1 | BU15: 1
A16: 12 | B16: 环保袋 | D16: 个 | E16: 0.75 | F16: 3159 | G16: =F16*E16 -> 2369.25 | H16: =SUMIF($N$4:$BW$4,$H$4,$N16:$BW16) -> 0 | I16: =+E16*H16 -> 0 | J16: =SUMIF($N$4:$BW$4,$J$4,N16:$BW16) -> 1101 | K16: =+E16*J16 -> 825.75 | L16: =+F16+H16-J16 -> 2058 | M16: =+E16*L16 -> 1543.5 | O16: 25 | Q16: 23 | S16: 38 | U16: 30 | W16: 39 | Y16: 34 | AA16: 30 | AC16: 38 | AE16: 32 | AG16: 41 | AI16: 26 | AK16: 36 | AM16: 43 | AO16: 29 | AQ16: 25 | AS16: 31 | AU16: 24 | AW16: 33 | AY16: 24 | BA16: 36 | BC16: 41 | BE16: 36 | BG16: 43 | BI16: 37 | BK16: 31 | BM16: 32 | BO16: 36 | BQ16: 40 | BS16: 52 | BU16: 56 | BW16: 60
A17: 13 | B17: 红茶 | D17: 包 | E17: 0.39 | F17: 772 | G17: =F17*E17 -> 301.08 | H17: =SUMIF($N$4:$BW$4,$H$4,$N17:$BW17) -> 0 | I17: =+E17*H17 -> 0 | J17: =SUMIF($N$4:$BW$4,$J$4,N17:$BW17) -> 565 | K17: =+E17*J17 -> 220.35 | L17: =+F17+H17-J17 -> 207 | M17: =+E17*L17 -> 80.73 | O17: 17 | Q17: 18 | S17: 19 | U17: 15 | W17: 16 | Y17: 19 | AA17: 17 | AC17: 21 | AE17: 18 | AG17: 23 | AI17: 18 | AK17: 20 | AM17: 24 | AO17: 17 | AQ17: 20 | AS17: 14 | AU17: 13 | AW17: 18 | AY17: 15 | BA17: 18 | BC17: 22 | BE17: 18 | BG17: 15 | BI17: 18 | BK17: 17 | BM17: 15 | BO17: 17 | BQ17: 19 | BS17: 21 | BU17: 22 | BW17: 21
A18: 14 | B18: 绿茶 | D18: 包 | E18: 0.39 | F18: 857 | G18: =F18*E18 -> 334.23 | H18: =SUMIF($N$4:$BW$4,$H$4,$N18:$BW18) -> 0 | I18: =+E18*H18 -> 0 | J18: =SUMIF($N$4:$BW$4,$J$4,N18:$BW18) -> 557 | K18: =+E18*J18 -> 217.23 | L18: =+F18+H18-J18 -> 300 | M18: =+E18*L18 -> 117 | O18: 19 | Q18: 16 | S18: 17 | U18: 16 | W18: 16 | Y18: 14 | AA18: 17 | AC18: 22 | AE18: 20 | AG18: 20 | AI18: 17 | AK18: 18 | AM18: 23 | AO18: 18 | AQ18: 19 | AS18: 16 | AU18: 15 | AW18: 19 | AY18: 13 | BA18: 19 | BC18: 23 | BE18: 16 | BG18: 15 | BI18: 17 | BK18: 19 | BM18: 13 | BO18: 17 | BQ18: 17 | BS18: 23 | BU18: 20 | BW18: 23
A19: 15 | B19: 洗发液 | D19: 瓶 | E19: 13.5 | F19: 422 | G19: =F19*E19 -> 5697 | H19: =SUMIF($N$4:$BW$4,$H$4,$N19:$BW19) -> 0 | I19: =+E19*H19 -> 0 | J19: =SUMIF($N$4:$BW$4,$J$4,N19:$BW19) -> 254 | K19: =+E19*J19 -> 3429 | L19: =+F19+H19-J19 -> 168 | M19: =+E19*L19 -> 2268 | O19: 6 | Q19: 7 | S19: 7 | U19: 8 | W19: 8 | Y19: 7 | AA19: 8 | AC19: 8 | AE19: 6 | AG19: 7 | AI19: 9 | AK19: 8 | AM19: 9 | AO19: 8 | AQ19: 9 | AS19: 8 | AU19: 8 | AW19: 10 | AY19: 8 | BA19: 10 | BC19: 11 | BE19: 9 | BG19: 10 | BI19: 8 | BK19: 9 | BM19: 8 | BO19: 8 | BQ19: 7 | BS19: 11 | BU19: 7 | BW19: 7
A20: 16 | B20: 沐浴液 | D20: 瓶 | E20: 13.5 | F20: 447 | G20: =F20*E20 -> 6034.5 | H20: =SUMIF($N$4:$BW$4,$H$4,$N20:$BW20) -> 0 | I20: =+E20*H20 -> 0 | J20: =SUMIF($N$4:$BW$4,$J$4,N20:$BW20) -> 248 | K20: =+E20*J20 -> 3348 | L20: =+F20+H20-J20 -> 199 | M20: =+E20*L20 -> 2686.5 | O20: 6 | Q20: 6 | S20: 7 | U20: 8 | W20: 7 | Y20: 8 | AA20: 6 | AC20: 6 | AE20: 7 | AG20: 8 | AI20: 7 | AK20: 8 | AM20: 7 | AO20: 8 | AQ20: 8 | AS20: 8 | AU20: 7 | AW20: 9 | AY20: 9 | BA20: 10 | BC20: 10 | BE20: 9 | BG20: 9 | BI20: 10 | BK20: 9 | BM20: 7 | BO20: 9 | BQ20: 7 | BS20: 12 | BU20: 10 | BW20: 6
A21: 17 | B21: 护发素 | D21: 瓶 | E21: 13.5 | F21: 476 | G21: =F21*E21 -> 6426 | H21: =SUMIF($N$4:$BW$4,$H$4,$N21:$BW21) -> 0 | I21: =+E21*H21 -> 0 | J21: =SUMIF($N$4:$BW$4,$J$4,N21:$BW21) -> 146 | K21: =+E21*J21 -> 1971 | L21: =+F21+H21-J21 -> 330 | M21: =+E21*L21 -> 4455 | O21: 5 | Q21: 4 | S21: 5 | U21: 4 | W21: 4 | Y21: 5 | AA21: 3 | AC21: 4 | AE21: 5 | AG21: 4 | AI21: 5 | AK21: 4 | AM21: 6 | AO21: 5 | AQ21: 4 | AS21: 5 | AU21: 5 | AW21: 6 | AY21: 4 | BA21: 6 | BC21: 4 | BE21: 6 | BG21: 5 | BI21: 6 | BK21: 5 | BM21: 4 | BO21: 4 | BQ21: 3 | BS21: 7 | BU21: 4 | BW21: 5
A22: 18 | B22: 厕纸 | D22: 卷 | E22: 0.75 | F22: 4725 | G22: =F22*E22 -> 3543.75 | H22: =SUMIF($N$4:$BW$4,$H$4,$N22:$BW22) -> 0 | I22: =+E22*H22 -> 0 | J22: =SUMIF($N$4:$BW$4,$J$4,N22:$BW22) -> 2883 | K22: =+E22*J22 -> 2162.25 | L22: =+F22+H22-J22 -> 1842 | M22: =+E22*L22 -> 1381.5 | O22: 81 | Q22: 98 | S22: 96 | U22: 83 | W22: 93 | Y22: 92 | AA22: 91 | AC22: 93 | AE22: 89 | AG22: 90 | AI22: 90 | AK22: 92 | AM22: 96 | AO22: 75 | AQ22: 86 | AS22: 92 | AU22: 82 | AW22: 96 | AY22: 89 | BA22: 93 | BC22: 95 | BE22: 97 | BG22: 93 | BI22: 97 | BK22: 102 | BM22: 93 | BO22: 92 | BQ22: 101 | BS22: 108 | BU22: 106 | BW22: 102
A23: 19 | B23: 抽纸 | D23: 包 | E23: 0.45 | F23: 4436 | G23: =F23*E23 -> 1996.2 | H23: =SUMIF($N$4:$BW$4,$H$4,$N23:$BW23) -> 0 | I23: =+E23*H23 -> 0 | J23: =SUMIF($N$4:$BW$4,$J$4,N23:$BW23) -> 3689 | K23: =+E23*J23 -> 1660.05 | L23: =+F23+H23-J23 -> 747 | M23: =+E23*L23 -> 336.15 | O23: 93 | Q23: 90 | S23: 921 | U23: 88 | W23: 89 | Y23: 94 | AA23: 92 | AC23: 95 | AE23: 92 | AG23: 92 | AI23: 85 | AK23: 88 | AM23: 91 | AO23: 80 | AQ23: 88 | AS23: 93 | AU23: 86 | AW23: 95 | AY23: 91 | BA23: 90 | BC23: 91 | BE23: 95 | BG23: 92 | BI23: 93 | BK23: 97 | BM23: 90 | BO23: 93 | BQ23: 99 | BS23: 106 | BU23: 102 | BW23: 98
A24: 20 | B24: 矿泉水 | D24: 瓶 | E24: 0.667 | F24: 15786 | G24: =F24*E24 -> 10529.262 | H24: =SUMIF($N$4:$BW$4,$H$4,$N24:$BW24) -> 0 | I24: =+E24*H24 -> 0 | J24: =SUMIF($N$4:$BW$4,$J$4,N24:$BW24) -> 10137 | K24: =+E24*J24 -> 6761.379 | L24: =+F24+H24-J24 -> 5649 | M24: =+E24*L24 -> 3767.883 | O24: 318 | Q24: 286 | S24: 325 | U24: 274 | W24: 287 | Y24: 345 | AA24: 330 | AC24: 336 | AE24: 352 | AG24: 340 | AI24: 333 | AK24: 332 | AM24: 343 | AO24: 314 | AQ24: 333 | AS24: 347 | AU24: 316 | AW24: 322 | AY24: 344 | BA24: 333 | BC24: 311 | BE24: 298 | BG24: 322 | BI24: 310 | BK24: 311 | BM24: 320 | BO24: 354 | BQ24: 331 | BS24: 342 | BU24: 341 | BW24: 387
A25: 21 | B25: 大黑垃圾袋 | D25: 个 | E25: 0.36 | F25: 1541 | G25: =F25*E25 -> 554.76 | H25: =SUMIF($N$4:$BW$4,$H$4,$N25:$BW25) -> 0 | I25: =+E25*H25 -> 0 | J25: =SUMIF($N$4:$BW$4,$J$4,N25:$BW25) -> 941 | K25: =+E25*J25 -> 338.76 | L25: =+F25+H25-J25 -> 600 | M25: =+E25*L25 -> 216 | O25: 28 | Q25: 32 | S25: 35 | U25: 32 | W25: 35 | Y25: 24 | AA25: 26 | AC25: 23 | AE25: 27 | AG25: 30 | AI25: 32 | AK25: 34 | AM25: 38 | AO25: 20 | AQ25: 29 | AS25: 26 | AU25: 22 | AW25: 29 | AY25: 27 | BA25: 30 | BC25: 32 | BE25: 33 | BG25: 35 | BI25: 32 | BK25: 36 | BM25: 32 | BO25: 29 | BQ25: 31 | BS25: 36 | BU25: 34 | BW25: 32
A26: 22 | B26: 小白垃圾袋 | D26: 个 | E26: 0.027 | F26: 15272 | G26: =F26*E26 -> 412.344 | H26: =SUMIF($N$4:$BW$4,$H$4,$N26:$BW26) -> 0 | I26: =+E26*H26 -> 0 | J26: =SUMIF($N$4:$BW$4,$J$4,N26:$BW26) -> 6862 | K26: =+E26*J26 -> 185.274 | L26: =+F26+H26-J26 -> 8410 | M26: =+E26*L26 -> 227.07 | O26: 204 | Q26: 211 | S26: 222 | U26: 217 | W26: 210 | Y26: 198 | AA26: 213 | AC26: 214 | AE26: 218 | AG26: 215 | AI26: 213 | AK26: 224 | AM26: 236 | AO26: 199 | AQ26: 217 | AS26: 223 | AU26: 208 | AW26: 221 | AY26: 227 | BA26: 231 | BC26: 236 | BE26: 228 | BG26: 231 | BI26: 221 | BK26: 234 | BM26: 227 | BO26: 224 | BQ26: 228 | BS26: 234 | BU26: 238 | BW26: 240
A27: 23 | B27: 茶颜悦色绿茶 | D27: 包 | E27: 0.43 | F27: 780 | G27: =F27*E27 -> 335.4 | H27: =SUMIF($N$4:$BW$4,$H$4,$N27:$BW27) -> 0 | I27: =+E27*H27 -> 0 | J27: =SUMIF($N$4:$BW$4,$J$4,N27:$BW27) -> 599 | K27: =+E27*J27 -> 257.57 | L27: =+F27+H27-J27 -> 181 | M27: =+E27*L27 -> 77.83 | O27: 18 | Q27: 19 | S27: 19 | U27: 23 | W27: 24 | Y27: 20 | AA27: 19 | AC27: 16 | AE27: 24 | AG27: 18 | AI27: 23 | AK27: 21 | AM27: 26 | AO27: 15 | AQ27: 18 | AS27: 21 | AU27: 16 | AW27: 22 | AY27: 23 | BA27: 24 | BC27: 19 | BE27: 16 | BG27: 14 | BI27: 17 | BK27: 18 | BM27: 15 | BO27: 18 | BQ27: 16 | BS27: 19 | BU27: 20 | BW27: 18
... A30: 26 | B30: 咖啡 | D30: 袋 | E30: 0.6 | F30: 3494 | G30: =F30*E30 -> 2096.4 | H30: =SUMIF($N$4:$BW$4,$H$4,$N30:$BW30) -> 0 | I30: =+E30*H30 -> 0 | J30: =SUMIF($N$4:$BW$4,$J$4,N30:$BW30) -> 2545 | K30: =+E30*J30 -> 1527 | L30: =+F30+H30-J30 -> 949 | M30: =+E30*L30 -> 569.4 | O30: 75 | Q30: 80 | S30: 83 | U30: 85 | W30: 82 | Y30: 76 | AA30: 80 | AC30: 78 | AE30: 84 | AG30: 81 | AI30: 83 | AK30: 86 | AM30: 75 | AO30: 69 | AQ30: 72 | AS30: 76 | AU30: 71 | AW30: 84 | AY30: 82 | BA30: 89 | BC30: 83 | BE30: 82 | BG30: 88 | BI30: 84 | BK30: 83 | BM30: 82 | BO30: 81 | BQ30: 83 | BS30: 93 | BU30: 97 | BW30: 98
A31: 27 | B31: 饮料维他水溶 | D31: 瓶 | E31: 1.5 | G31: =F31*E31 -> 0 | H31: =SUMIF($N$4:$BW$4,$H$4,$N31:$BW31) -> 3600 | I31: =+E31*H31 -> 5400 | J31: =SUMIF($N$4:$BW$4,$J$4,N31:$BW31) -> 2641 | K31: =+E31*J31 -> 3961.5 | L31: =+F31+H31-J31 -> 959 | M31: =+E31*L31 -> 1438.5 | AL31: 1200 | AO31: 266 | AQ31: 128 | AS31: 137 | AU31: 152 | AW31: 142 | AY31: 135 | AZ31: 2400 | BA31: 130 | BC31: 141 | BE31: 145 | BG31: 147 | BI31: 127 | BK31: 137 | BM31: 122 | BO31: 137 | BQ31: 133 | BS31: 154 | BU31: 148 | BW31: 160
A32: 28 | G32: =F32*E32 -> 0 | H32: =SUMIF($N$4:$BW$4,$H$4,$N32:$BW32) -> 0 | I32: =+E32*H32 -> 0 | J32: =SUMIF($N$4:$BW$4,$J$4,N32:$BW32) -> 0 | K32: =+E32*J32 -> 0 | L32: =+F32+H32-J32 -> 0 | M32: =+E32*L32 -> 0
A33: 29 | G33: =F33*E33 -> 0 | H33: =SUMIF($N$4:$BW$4,$H$4,$N33:$BW33) -> 0 | I33: =+E33*H33 -> 0 | J33: =SUMIF($N$4:$BW$4,$J$4,N33:$BW33) -> 0 | K33: =+E33*J33 -> 0 | L33: =+F33+H33-J33 -> 0 | M33: =+E33*L33 -> 0
A34: 30 | G34: =F34*E34 -> 0 | H34: =SUMIF($N$4:$BW$4,$H$4,$N34:$BW34) -> 0 | I34: =+E34*H34 -> 0 | J34: =SUMIF($N$4:$BW$4,$J$4,N34:$BW34) -> 0 | K34: =+E34*J34 -> 0 | L34: =+F34+H34-J34 -> 0 | M34: =+E34*L34 -> 0
A35: 31 | G35: =F35*E35 -> 0 | H35: =SUMIF($N$4:$BW$4,$H$4,$N35:$BW35) -> 0 | I35: =+E35*H35 -> 0 | J35: =SUMIF($N$4:$BW$4,$J$4,N35:$BW35) -> 0 | K35: =+E35*J35 -> 0 | L35: =+F35+H35-J35 -> 0 | M35: =+E35*L35 -> 0
A36: 32 | G36: =F36*E36 -> 0 | H36: =SUMIF($N$4:$BW$4,$H$4,$N36:$BW36) -> 0 | I36: =+E36*H36 -> 0 | J36: =SUMIF($N$4:$BW$4,$J$4,N36:$BW36) -> 0 | K36: =+E36*J36 -> 0 | L36: =+F36+H36-J36 -> 0 | M36: =+E36*L36 -> 0
A37: 33 | G37: =F37*E37 -> 0 | H37: =SUMIF($N$4:$BW$4,$H$4,$N37:$BW37) -> 0 | I37: =+E37*H37 -> 0 | J37: =SUMIF($N$4:$BW$4,$J$4,N37:$BW37) -> 0 | K37: =+E37*J37 -> 0 | L37: =+F37+H37-J37 -> 0 | M37: =+E37*L37 -> 0
A38: 34 | G38: =F38*E38 -> 0 | H38: =SUMIF($N$4:$BW$4,$H$4,$N38:$BW38) -> 0 | I38: =+E38*H38 -> 0 | J38: =SUMIF($N$4:$BW$4,$J$4,N38:$BW38) -> 0 | K38: =+E38*J38 -> 0 | L38: =+F38+H38-J38 -> 0 | M38: =+E38*L38 -> 0
